Workbook

Sheet C1E10
D2: b/300 | I2: b/200 | K2: -1 | L2: -0.001 | N2: b/100
A3: depl | B3: load | D3: X | E3: LPF | F3: U_33__33 | G3: RF_33__33 | I3: X | J3: LPF | K3: U_33__33 | L3: RF_33__33 | N3: X | O3: LPF | P3: U_33__33 | Q3: RF_33__33
A4: 0 | B4: 0 | D4: 0 | E4: 0 | F4: 0 | G4: 0 | I4: 0 | J4: 0 | K4: -0.00969142 | L4: 1.2048e-07 | N4: 0 | O4: 0 | P4: -0.0193694 | Q4: 2.20601e-07
A5: 2.0779221 | B5: 42.339833 | D5: 0.5 | E5: 0.458298 | F5: 1.18838 | G5: 30.761 | I5: 0.5 | J5: 0.458392 | K5: -1.09075 | L5: 30.7673 | N5: 0.5 | O5: 0.458002 | P5: -1.11063 | Q5: 30.7411
A6: 3.3116883 | B6: 71.866295 | D6: 1 | E6: 0.845786 | F6: 2.37417 | G6: 56.7691 | I6: 1 | J6: 0.846048 | K6: -2.17824 | L6: 56.7868 | N6: 1 | O6: 0.844707 | P6: -2.20823 | Q6: 56.6967
A7: 5.4545455 | B7: 106.40669 | D7: 1.5 | E7: 1.17752 | F7: 3.56463 | G7: 79.0351 | I7: 1.5 | J7: 1.17795 | K7: -3.27062 | L7: 79.0642 | N7: 1.5 | O7: 1.17534 | P7: -3.31064 | Q7: 78.8886
A8: 7.2727273 | B8: 130.91922 | D8: 2 | E8: 1.46463 | F8: 4.75872 | G8: 98.3058 | I8: 2 | J8: 1.46521 | K8: -4.36682 | L8: 98.3446 | N8: 2 | O8: 1.46114 | P8: -4.41679 | Q8: 98.0718
A9: 9.7402597 | B9: 156.54596 | D9: 2.5 | E9: 1.71549 | F9: 5.95569 | G9: 115.144 | I9: 2.5 | J9: 1.71618 | K9: -5.46604 | L9: 115.19 | N9: 2.5 | O9: 1.71058 | P9: -5.5259 | Q9: 114.814
A10: 12.337662 | B10: 177.71588 | D10: 3 | E10: 1.93654 | F10: 7.155 | G10: 129.98 | I10: 3 | J10: 1.9373 | K10: -6.5677 | L10: 130.032 | N10: 3 | O10: 1.93015 | P10: -6.63739 | Q10: 129.552
A11: 15.194805 | B11: 197.77159 | D11: 3.5 | E11: 2.13276 | F11: 8.3562 | G11: 143.151 | I11: 3.5 | J11: 2.13357 | K11: -7.67136 | L11: 143.205 | N11: 3.5 | O11: 2.12487 | P11: -7.75083 | Q11: 142.621
A12: 18.181818 | B12: 213.64903 | D12: 4 | E12: 2.30812 | F12: 9.55897 | G12: 154.921 | I12: 4 | J12: 2.30894 | K12: -8.77667 | L12: 154.976 | N12: 4 | O12: 2.29872 | P12: -8.86587 | Q12: 154.29
A13: 21.428571 | B13: 228.96936 | D13: 4.5 | E13: 2.46575 | F13: 10.7631 | G13: 165.501 | I13: 4.5 | J13: 2.46658 | K13: -9.88336 | L13: 165.557 | N13: 4.5 | O13: 2.45488 | P13: -9.98226 | Q13: 164.772
A14: 24.155844 | B14: 237.60446 | D14: 5 | E14: 2.60823 | F14: 11.9682 | G14: 175.064 | I14: 5 | J14: 2.60902 | K14: -10.9912 | L14: 175.118 | N14: 5 | O14: 2.59591 | P14: -11.0998 | Q14: 174.237
A15: 26.298701 | B15: 246.51811 | D15: 5.5 | E15: 2.73762 | F15: 13.1743 | G15: 183.749 | I15: 5.5 | J15: 2.73838 | K15: -12.1 | L15: 183.8 | N15: 5.5 | O15: 2.7239 | P15: -12.2182 | Q15: 182.828
... A22: 90.519481 | B22: 239.83287 | D22: 9 | E22: 3.3917 | F22: 21.6331 | G22: 227.651 | I22: 9 | J22: 3.39194 | K22: -19.8794 | L22: 227.667 | N22: 9 | O22: 3.36929 | P22: -20.0645 | Q22: 226.147
D23: 9.5 | E23: 3.46006 | F23: 22.8428 | G23: 232.239 | I23: 9.5 | J23: 3.46021 | K23: -20.9923 | L23: 232.249 | N23: 9.5 | O23: 3.43656 | P23: -21.1869 | Q23: 230.662
D24: 10 | E24: 3.52399 | F24: 24.0528 | G24: 236.53 | I24: 10 | J24: 3.52404 | K24: -22.1054 | L24: 236.533 | N24: 10 | O24: 3.49944 | P24: -22.3096 | Q24: 234.882
D25: 10.5 | E25: 3.5839 | F25: 25.2628 | G25: 240.551 | I25: 10.5 | J25: 3.58385 | K25: -23.2187 | L25: 240.548 | N25: 10.5 | O25: 3.55832 | P25: -23.4324 | Q25: 238.835
D26: 11 | E26: 3.64017 | F26: 26.473 | G26: 244.328 | I26: 11 | J26: 3.64002 | K26: -24.3322 | L26: 244.318 | N26: 11 | O26: 3.61359 | P26: -24.5554 | Q26: 242.544
D27: 11.5 | E27: 3.69311 | F27: 27.6832 | G27: 247.882 | I27: 11.5 | J27: 3.69286 | K27: -25.4458 | L27: 247.864 | N27: 11.5 | O27: 3.66548 | P27: -25.6786 | Q27: 246.027
D28: 12 | E28: 3.74302 | F28: 28.8935 | G28: 251.232 | I28: 12 | J28: 3.74266 | K28: -26.5595 | L28: 251.207 | N28: 12 | O28: 3.71402 | P28: -26.8023 | Q28: 249.285
D29: 12.5 | E29: 3.78996 | F29: 30.1041 | G29: 254.382 | I29: 12.5 | J29: 3.78967 | K29: -27.6733 | L29: 254.363 | N29: 12.5 | O29: 3.7595 | P29: -27.9263 | Q29: 252.338
D30: 13 | E30: 3.83287 | F30: 31.3169 | G30: 257.262 | I30: 13 | J30: 3.8339 | K30: -28.7874 | L30: 257.332 | N30: 13 | O30: 3.80162 | P30: -29.0513 | Q30: 255.165
D31: 13.5 | E31: 3.87006 | F31: 32.5337 | G31: 259.759 | I31: 13.5 | J31: 3.87513 | K31: -29.9025 | L31: 260.099 | N31: 13.5 | O31: 3.83971 | P31: -30.1782 | Q31: 257.721
D32: 14 | E32: 3.90043 | F32: 33.7552 | G32: 261.797 | I32: 14 | J32: 3.91245 | K32: -31.0196 | L32: 262.604 | N32: 14 | O32: 3.87429 | P32: -31.306 | Q32: 260.042
D33: 14.5 | E33: 3.92552 | F33: 34.9784 | G33: 263.481 | I33: 14.5 | J33: 3.94567 | K33: -32.1387 | L33: 264.833 | N33: 14.5 | O33: 3.90554 | P33: -32.4348 | Q33: 262.14
D34: 15 | E34: 3.94723 | F34: 36.2015 | G34: 264.938 | I34: 15 | J34: 3.97445 | K34: -33.2602 | L34: 266.765 | N34: 15 | O34: 3.93273 | P34: -33.5658 | Q34: 263.965
... D79: 37.5 | E79: 3.46286 | F79: 92.1256 | G79: 232.427 | I79: 37.5 | J79: 3.628 | K79: -84.5497 | L79: 243.511 | N79: 37.5 | O79: 3.58477 | P79: -85.3229 | Q79: 240.61
G80: =MAX(G4:G79) -> 269.036 | I80: 38 | J80: 3.60829 | K80: -85.7116 | L80: 242.188 | Q80: =MAX(Q4:Q79) -> 270.956
I81: 38.5 | J81: 3.58813 | K81: -86.8777 | L81: 240.835
I82: 39 | J82: 3.56748 | K82: -88.0486 | L82: 239.449
I83: 39.5 | J83: 3.54642 | K83: -89.2231 | L83: 238.036
I84: 40 | J84: 3.52533 | K84: -90.3978 | L84: 236.62
I85: 40.5 | J85: 3.50433 | K85: -91.5715 | L85: 235.211
I86: 41 | J86: 3.48348 | K86: -92.7444 | L86: 233.811
I87: 41.5 | J87: 3.46278 | K87: -93.9165 | L87: 232.422
I88: 42 | J88: 3.44222 | K88: -95.0884 | L88: 231.042
I89: 42.5 | J89: 3.42172 | K89: -96.2611 | L89: 229.666
I90: 43 | J90: 3.40124 | K90: -97.435 | L90: 228.291
I91: 43.5 | J91: 3.38086 | K91: -98.6093 | L91: 226.923
...

Sheet C1E30
D2: b/300 | G2: -0.001 | I2: b/200 | K2: -1 | N2: b/100
A3: x | B3: y | D3: X | E3: LPF | F3: U_34__34 | G3: RF_34__34 | I3: X | J3: LPF | K3: U_34__34 | L3: RF_34__34 | N3: X | O3: LPF | P3: U_34__34 | Q3: RF_34__34
A4: 0 | B4: 0 | D4: 0 | E4: 0 | F4: 0 | G4: 0 | I4: 0 | J4: 0 | K4: -0.0102552 | L4: 6.2229e-08 | N4: 0 | O4: 0 | P4: -0.0203565 | Q4: 5.46771e-07
A5: 2.987013 | B5: 26.740947 | D5: 0.5 | E5: 0.467945 | F5: 2.61183 | G5: 23.6347 | I5: 0.5 | J5: 0.467936 | K5: -2.54507 | L5: 23.6343 | N5: 0.5 | O5: 0.467631 | P5: -2.57717 | Q5: 23.6188
A6: 5.8441558 | B6: 49.02507 | D6: 1 | E6: 0.879484 | F6: 5.22322 | G6: 44.4205 | I6: 1 | J6: 0.879444 | K6: -5.08802 | L6: 44.4185 | N6: 1 | O6: 0.878353 | P6: -5.14215 | Q6: 44.3634
A7: 11.428571 | B7: 85.236769 | D7: 1.5 | E7: 1.24422 | F7: 7.84112 | G7: 62.8425 | I7: 1.5 | J7: 1.24413 | K7: -7.63759 | L7: 62.8381 | N7: 1.5 | O7: 1.24193 | P7: -7.71376 | Q7: 62.727
A8: 16.363636 | B8: 112.53482 | D8: 2 | E8: 1.56971 | F8: 10.4643 | G8: 79.2821 | I8: 2 | J8: 1.56956 | K8: -10.1926 | L8: 79.2746 | N8: 2 | O8: 1.56603 | P8: -10.2908 | Q8: 79.0964
A9: 23.831169 | B9: 143.45404 | D9: 2.5 | E9: 1.86197 | F9: 13.0918 | G9: 94.0433 | I9: 2.5 | J9: 1.86174 | K9: -12.752 | L9: 94.0319 | N9: 2.5 | O9: 1.85674 | P9: -12.8723 | Q9: 93.7793
A10: 30.779221 | B10: 162.95265 | D10: 3 | E10: 2.12584 | F10: 15.7228 | G10: 107.371 | I10: 3 | J10: 2.12553 | K10: -15.3151 | L10: 107.355 | N10: 3 | O10: 2.11896 | P10: -15.4574 | Q10: 107.023
A11: 37.012987 | B11: 178.27298 | D11: 3.5 | E11: 2.36529 | F11: 18.3567 | G11: 119.465 | I11: 3.5 | J11: 2.36487 | K11: -17.8811 | L11: 119.444 | N11: 3.5 | O11: 2.35667 | P11: -18.0454 | Q11: 119.03
A12: 43.246753 | B12: 189.41504 | D12: 4 | E12: 2.58356 | F12: 20.9927 | G12: 130.489 | I12: 4 | J12: 2.58303 | K12: -20.4495 | L12: 130.463 | N12: 4 | O12: 2.57314 | P12: -20.6359 | Q12: 129.963
A13: 55.064935 | B13: 198.88579 | D13: 4.5 | E13: 2.78334 | F13: 23.6306 | G13: 140.579 | I13: 4.5 | J13: 2.78268 | K13: -23.0198 | L13: 140.546 | N13: 4.5 | O13: 2.77108 | P13: -23.2282 | Q13: 139.96
A14: 62.727273 | B14: 200.83565 | D14: 5 | E14: 2.96682 | F14: 26.2698 | G14: 149.847 | I14: 5 | J14: 2.96607 | K14: -25.5916 | L14: 149.809 | N14: 5 | O14: 2.95274 | P14: -25.822 | Q14: 149.136
A15: 72.077922 | B15: 196.65738 | D15: 5.5 | E15: 3.13593 | F15: 28.91 | G15: 158.388 | I15: 5.5 | J15: 3.13509 | K15: -28.1645 | L15: 158.345 | N15: 5.5 | O15: 3.12004 | P15: -28.417 | Q15: 157.586
... A18: 99.61039 | B18: 172.70195 | D18: 7 | E18: 3.56376 | F18: 36.8464 | G18: 179.997 | I18: 7 | J18: 3.56452 | K18: -35.896 | L18: 180.035 | N18: 7 | O18: 3.53724 | P18: -36.2208 | Q18: 178.657
D19: 7.5 | E19: 3.66436 | F19: 39.5153 | G19: 185.078 | I19: 7.5 | J19: 3.67229 | K19: -38.4907 | L19: 185.478 | N19: 7.5 | O19: 3.6426 | P19: -38.8359 | Q19: 183.978
D20: 8 | E20: 3.74975 | F20: 42.1831 | G20: 189.391 | I20: 8 | J20: 3.76044 | K20: -41.0927 | L20: 189.931 | N20: 8 | O20: 3.7304 | P20: -41.4575 | Q20: 188.413
D21: 8.5 | E21: 3.81705 | F21: 44.8615 | G21: 192.789 | I21: 8.5 | J21: 3.83261 | K21: -43.6986 | L21: 193.575 | N21: 8.5 | O21: 3.80149 | P21: -44.0863 | Q21: 192.004
D22: 9 | E22: 3.87056 | F22: 47.541 | G22: 195.492 | I22: 9 | J22: 3.89106 | K22: -46.3083 | L22: 196.528 | N22: 9 | O22: 3.85924 | P22: -46.7178 | Q22: 194.921
D23: 9.5 | E23: 3.91473 | F23: 50.2192 | G23: 197.723 | I23: 9.5 | J23: 3.93668 | K23: -48.9231 | L23: 198.832 | N23: 9.5 | O23: 3.90485 | P23: -49.3537 | Q23: 197.224
D24: 10 | E24: 3.9469 | F24: 52.9073 | G24: 199.348 | I24: 10 | J24: 3.97209 | K24: -51.5394 | L24: 200.62 | N24: 10 | O24: 3.94073 | P24: -51.9913 | Q24: 199.036
D25: 10.5 | E25: 3.9698 | F25: 55.5968 | G25: 200.505 | I25: 10.5 | J25: 3.99987 | K25: -54.1557 | L25: 202.024 | N25: 10.5 | O25: 3.96781 | P25: -54.6316 | Q25: 200.404
D26: 11 | E26: 3.98829 | F26: 58.2784 | G26: 201.439 | I26: 11 | J26: 4.02028 | K26: -56.7743 | L26: 203.054 | N26: 11 | O26: 3.98806 | P26: -57.2724 | Q26: 201.427
D27: 11.5 | E27: 4.00353 | F27: 60.955 | G27: 202.208 | I27: 11.5 | J27: 4.03458 | K27: -59.3935 | L27: 203.777 | N27: 11.5 | O27: 4.00278 | P27: -59.9124 | Q27: 202.17
D28: 12 | E28: 4.01355 | F28: 63.6367 | G28: 202.714 | I28: 12 | J28: 4.04489 | K28: -62.0087 | L28: 204.297 | N28: 12 | O28: 4.01311 | P28: -62.5509 | Q28: 202.692
D29: 12.5 | E29: 4.01798 | F29: 66.3235 | G29: 202.938 | I29: 12.5 | J29: 4.05223 | K29: -64.6205 | L29: 204.668 | N29: 12.5 | O29: 4.01923 | P29: -65.1901 | Q29: 203.001
D30: 13 | E30: 4.01293 | F30: 69.0369 | G30: 202.683 | I30: 13 | J30: 4.05343 | K30: -67.2463 | L30: 204.729 | N30: 13 | O30: 4.01871 | P30: -67.8444 | Q30: 202.975
... D42: 19 | E42: 3.69192 | F42: 102.048 | G42: 186.47 | I42: 19 | J42: 3.75141 | K42: -99.3933 | L42: 189.474 | N42: 19 | O42: 3.70689 | P42: -100.325 | Q42: 187.226
G43: =MAX(G4:G42) -> 202.938 | I43: 19.5 | J43: 3.71461 | K43: -102.103 | L43: 187.616 | N43: 19.5 | O43: 3.66938 | P43: -103.066 | Q43: 185.331
I44: 20 | J44: 3.67742 | K44: -104.816 | L44: 185.737 | N44: 20 | O44: 3.63093 | P44: -105.818 | Q44: 183.389
I45: 20.5 | J45: 3.63841 | K45: -107.553 | L45: 183.767 | N45: 20.5 | O45: 3.59097 | P45: -108.59 | Q45: 181.371
I46: 21 | J46: 3.59899 | K46: -110.292 | L46: 181.776 | N46: 21 | O46: 3.55073 | P46: -111.364 | Q46: 179.339
I47: 21.5 | J47: 3.5598 | K47: -113.028 | L47: 179.797 | N47: 21.5 | O47: 3.51055 | P47: -114.139 | Q47: 177.309
I48: 22 | J48: 3.52072 | K48: -115.766 | L48: 177.823 | N48: 22 | O48: 3.47021 | P48: -116.921 | Q48: 175.272
I49: 22.5 | J49: 3.48164 | K49: -118.509 | L49: 175.849 | N49: 22.5 | O49: 3.43006 | P49: -119.706 | Q49: 173.244
I50: 23 | J50: 3.44298 | K50: -121.25 | L50: 173.896 | N50: 23 | O50: 3.39023 | P50: -122.49 | Q50: 171.232
I51: 23.5 | J51: 3.40485 | K51: -123.988 | L51: 171.971 | N51: 23.5 | O51: 3.35067 | P51: -125.279 | Q51: 169.234
I52: 24 | J52: 3.36702 | K52: -126.729 | L52: 170.06 | N52: 24 | O52: 3.31054 | P52: -128.089 | Q52: 167.207
I53: 24.5 | J53: 3.32859 | K53: -129.491 | L53: 168.119 | N53: 24.5 | O53: 3.26962 | P53: -130.924 | Q53: 165.14
I54: 25 | J54: 3.28993 | K54: -132.265 | L54: 166.166 | N54: 25 | O54: 3.22877 | P54: -133.768 | Q54: 163.077
...

Sheet C1E60
D2: b/300 | I2: b/200 | K2: -1 | L2: -0.001 | N2: b/100
A3: x | B3: y | D3: X | E3: LPF | F3: U_35__35 | G3: RF_35__35 | I3: X | J3: LPF | K3: U_35__35 | L3: RF_35__35 | N3: X | O3: LPF | P3: U_35__35 | Q3: RF_35__35
A4: 0 | B4: 0 | D4: 0 | E4: 0 | F4: 0 | G4: 0 | I4: 0 | J4: 0 | K4: -0.0100871 | L4: 1.51893e-06 | N4: 0 | O4: 0 | P4: -0.0198874 | Q4: 5.88846e-07
A5: 4.8051948 | B5: 16.43454 | D5: 0.5 | E5: 0.478022 | F5: 3.43877 | G5: 16.1153 | I5: 0.5 | J5: 0.477985 | K5: -3.40143 | L5: 16.1141 | N5: 0.5 | O5: 0.47776 | P5: -3.44015 | Q5: 16.1065
A6: 10.519481 | B6: 36.490251 | D6: 1 | E6: 0.915977 | F6: 6.87413 | G6: 30.8799 | I6: 1 | J6: 0.915832 | K6: -6.79849 | L6: 30.875 | N6: 1 | O6: 0.91501 | P6: -6.86618 | Q6: 30.8473
A7: 21.168831 | B7: 64.902507 | D7: 1.5 | E7: 1.31872 | F7: 10.3139 | G7: 44.4575 | I7: 1.5 | J7: 1.31841 | K7: -10.2001 | L7: 44.4469 | N7: 1.5 | O7: 1.3167 | P7: -10.2969 | Q7: 44.3891
A8: 27.012987 | B8: 78.551532 | D8: 2 | E8: 1.69037 | F8: 13.7572 | G8: 56.9866 | I8: 2 | J8: 1.68984 | K8: -13.6054 | L8: 56.9688 | N8: 2 | O8: 1.68699 | P8: -13.7312 | Q8: 56.8727
A9: 36.233766 | B9: 98.885794 | D9: 2.5 | E9: 2.03441 | F9: 17.2031 | G9: 68.585 | I9: 2.5 | J9: 2.03363 | K9: -17.0135 | L9: 68.5588 | N9: 2.5 | O9: 2.02944 | P9: -17.1683 | Q9: 68.4176
A10: 47.532468 | B10: 115.87744 | D10: 3 | E10: 2.35384 | F10: 20.6508 | G10: 79.3538 | I10: 3 | J10: 2.35277 | K10: -20.4236 | L10: 79.3178 | N10: 3 | O10: 2.34708 | P10: -20.6075 | Q10: 79.126
A11: 58.311688 | B11: 127.29805 | D11: 3.5 | E11: 2.65123 | F11: 24.0996 | G11: 89.3796 | I11: 3.5 | J11: 2.64985 | K11: -23.835 | L11: 89.333 | N11: 3.5 | O11: 2.64252 | P11: -24.048 | Q11: 89.0859
A12: 66.623377 | B12: 132.03343 | D12: 4 | E12: 2.92882 | F12: 27.549 | G12: 98.7379 | I12: 4 | J12: 2.9271 | K12: -27.2471 | L12: 98.6798 | N12: 4 | O12: 2.91801 | P12: -27.4892 | Q12: 98.3733
A13: 77.402597 | B13: 133.70474 | D13: 4.5 | E13: 3.18855 | F13: 30.9983 | G13: 107.494 | I13: 4.5 | J13: 3.18647 | K13: -30.6593 | L13: 107.424 | N13: 4.5 | O13: 3.17551 | P13: -30.9305 | Q13: 107.054
A14: 91.428571 | B14: 134.47632 | D14: 5 | E14: 3.43212 | F14: 34.4471 | G14: 115.705 | I14: 5 | J14: 3.42966 | K14: -34.0712 | L14: 115.622 | N14: 5 | O14: 3.41566 | P14: -34.3728 | Q14: 115.15
A15: 107.01299 | B15: 130.85515 | D15: 5.5 | E15: 3.65832 | F15: 37.8994 | G15: 123.331 | I15: 5.5 | J15: 3.65494 | K15: -37.4871 | L15: 123.217 | N15: 5.5 | O15: 3.63368 | P15: -37.8224 | Q15: 122.501
... A18: 151.68831 | B18: 116.43454 | D18: 7 | E18: 4.14143 | F18: 48.3342 | G18: 139.618 | I18: 7 | J18: 4.14702 | K18: -47.8063 | L18: 139.807 | N18: 7 | O18: 4.11992 | P18: -48.2244 | Q18: 138.893
D19: 7.5 | E19: 4.25143 | F19: 51.8219 | G19: 143.326 | I19: 7.5 | J19: 4.25933 | K19: -51.2563 | L19: 143.593 | N19: 7.5 | O19: 4.23133 | P19: -51.7034 | Q19: 142.649
D20: 8 | E20: 4.34013 | F20: 55.3139 | G20: 146.317 | I20: 8 | J20: 4.35072 | K20: -54.7108 | L20: 146.674 | N20: 8 | O20: 4.32344 | P20: -55.1841 | Q20: 145.754
D21: 8.5 | E21: 4.41591 | F21: 58.7986 | G21: 148.872 | I21: 8.5 | J21: 4.42743 | K21: -58.1616 | L21: 149.26 | N21: 8.5 | O21: 4.39911 | P21: -58.6677 | Q21: 148.305
D22: 9 | E22: 4.47718 | F22: 62.2891 | G22: 150.937 | I22: 9 | J22: 4.49049 | K22: -61.6149 | L22: 151.386 | N22: 9 | O22: 4.46153 | P22: -62.15 | Q22: 150.409
D23: 9.5 | E23: 4.52741 | F23: 65.7762 | G23: 152.63 | I23: 9.5 | J23: 4.54217 | K23: -65.0664 | L23: 153.128 | N23: 9.5 | O23: 4.51353 | P23: -65.629 | Q23: 152.163
D24: 10 | E24: 4.56349 | F24: 69.2854 | G24: 153.847 | I24: 10 | J24: 4.58182 | K24: -68.5297 | L24: 154.465 | N24: 10 | O24: 4.55101 | P24: -69.1303 | Q24: 153.426
D25: 10.5 | E25: 4.58627 | F25: 72.8076 | G25: 154.615 | I25: 10.5 | J25: 4.60536 | K25: -72.0186 | L25: 155.258 | N25: 10.5 | O25: 4.57261 | P25: -72.6534 | Q25: 154.154
D26: 11 | E26: 4.60033 | F26: 76.3285 | G26: 155.089 | I26: 11 | J26: 4.62057 | K26: -75.5037 | L26: 155.771 | N26: 11 | O26: 4.58672 | P26: -76.1683 | Q26: 154.63
D27: 11.125 | E27: 4.60174 | F27: 77.2146 | G27: 155.136 | I27: 11.125 | J27: 4.62313 | K27: -76.3755 | L27: 155.857 | N27: 11.125 | O27: 4.58878 | P27: -77.0493 | Q27: 154.699
D28: 11.25 | E28: 4.60172 | F28: 78.1058 | G28: 155.135 | I28: 11.25 | J28: 4.62462 | K28: -77.2511 | L28: 155.908 | N28: 11.25 | O28: 4.58976 | P28: -77.9341 | Q28: 154.732
D29: 11.375 | E29: 4.60084 | F29: 78.9988 | G29: 155.106 | I29: 11.375 | J29: 4.62484 | K29: -78.1314 | L29: 155.915 | N29: 11.375 | O29: 4.58964 | P29: -78.8228 | Q29: 154.728
D30: 11.5 | E30: 4.59932 | F30: 79.8923 | G30: 155.055 | I30: 11.5 | J30: 4.62403 | K30: -79.0146 | L30: 155.888 | N30: 11.5 | O30: 4.5886 | P30: -79.7139 | Q30: 154.693
... D79: 17.625 | E79: 4.20221 | F79: 124.13 | G79: 141.667 | I79: 17.625 | J79: 4.23281 | K79: -122.808 | L79: 142.699 | N79: 17.625 | O79: 4.17625 | P79: -124.034 | Q79: 140.792
G80: =MAX(G4:G79) -> 155.136 | L80: =MAX(L4:L79) -> 155.915 | Q80: =MAX(Q4:Q79) -> 154.732

Sheet C2E10
B2: -1 | D2: b/300 | I2: b/200 | K2: -0.001 | L2: -1 | N2: b/100
A3: x | B3: y | D3: X | E3: LPF | F3: U_36__36 | G3: RF_36__36 | I3: X | J3: LPF | K3: U_36__36 | L3: RF_36__36 | N3: X | O3: LPF | P3: U_36__36 | Q3: RF_36__36
A4: 0 | B4: 0 | D4: 0 | E4: 0 | F4: 0 | G4: 0 | I4: 0 | J4: 0 | K4: 0.0569256 | L4: -1.09329e-09 | N4: 0 | O4: 0 | P4: 0.112675 | Q4: -1.9898e-09
A5: 0.86760974 | B5: 50.674553 | D5: 0.5 | E5: 0.466129 | F5: 0.989772 | G5: 86.6988 | I5: 0.5 | J5: 0.466113 | K5: -0.89292 | L5: 86.6959 | N5: 0.5 | O5: 0.46451 | P5: -0.846378 | Q5: 86.3976
A6: 1.8851367 | B6: 123.49674 | D6: 1 | E6: 0.872323 | F6: 2.02516 | G6: 162.25 | I6: 1 | J6: 0.872109 | K6: -1.85472 | L6: 162.21 | N6: 1 | O6: 0.866258 | P6: -1.81921 | Q6: 161.122
A7: 3.4923046 | B7: 230.30088 | D7: 1.5 | E7: 1.2288 | F7: 3.06906 | G7: 228.555 | I7: 1.5 | J7: 1.22813 | K7: -2.82583 | L7: 228.429 | N7: 1.5 | O7: 1.21612 | P7: -2.80284 | Q7: 226.196
A8: 5.4943438 | B8: 334.06413 | D8: 2 | E8: 1.54377 | F8: 4.11966 | G8: 287.137 | I8: 2 | J8: 1.54235 | K8: -3.8043 | L8: 286.874 | N8: 2 | O8: 1.52283 | P8: -3.79502 | Q8: 283.243
A9: 7.4207843 | B9: 412.94233 | D9: 2.5 | E9: 1.82379 | F9: 5.1756 | G9: 339.221 | I9: 2.5 | J9: 1.82138 | K9: -4.78865 | L9: 338.773 | N9: 2.5 | O9: 1.79338 | P9: -4.79408 | Q9: 333.563
A10: 10.1185 | B10: 506.37636 | D10: 3 | E10: 2.0742 | F10: 6.23585 | G10: 385.797 | I10: 3 | J10: 2.07056 | K10: -5.77775 | L10: 385.12 | N10: 3 | O10: 2.03338 | P10: -5.79872 | Q10: 378.204
A11: 12.927901 | B11: 579.77834 | D11: 3.5 | E11: 2.29932 | F11: 7.2996 | G11: 427.668 | I11: 3.5 | J11: 2.29425 | K11: -6.77074 | L11: 426.725 | N11: 3.5 | O11: 2.2474 | P11: -6.80794 | Q11: 418.012
A12: 15.639847 | B12: 634.36541 | D12: 4 | E12: 2.50269 | F12: 8.36621 | G12: 465.495 | I12: 4 | J12: 2.496 | K12: -7.7669 | L12: 464.25 | N12: 4 | O12: 2.43915 | P12: -7.82093 | Q12: 453.675
A13: 19.001637 | B13: 681.65886 | D13: 4.5 | E13: 2.68723 | F13: 9.43519 | G13: 499.818 | I13: 4.5 | J13: 2.67876 | K13: -8.7657 | L13: 498.242 | N13: 4.5 | O13: 2.61164 | P13: -8.83707 | Q13: 485.758
A14: 22.174731 | B14: 718.02953 | D14: 5 | E14: 2.85535 | F14: 10.5061 | G14: 531.087 | I14: 5 | J14: 2.84495 | K14: -9.76668 | L14: 529.153 | N14: 5 | O14: 2.76738 | P14: -9.85584 | Q14: 514.726
A15: 25.483627 | B15: 738.00967 | D15: 5.5 | E15: 3.00907 | F15: 11.5786 | G15: 559.68 | I15: 5.5 | J15: 2.99661 | K15: -10.7695 | L15: 557.362 | N15: 5.5 | O15: 2.90845 | P15: -10.8768 | Q15: 540.964
... A23: 55.939947 | B23: 624.0422 | D23: 9.5 | E23: 3.80642 | F23: 20.205 | G23: 707.984 | I23: 9.5 | J23: 3.78525 | K23: -18.8406 | L23: 704.048 | N23: 9.5 | O23: 3.58208 | P23: -19.1188 | Q23: 666.257
D24: 10 | E24: 3.84922 | F24: 21.2911 | G24: 715.945 | I24: 10 | J24: 3.83092 | K24: -19.8565 | L24: 712.542 | N24: 10 | O24: 3.61805 | P24: -20.1582 | Q24: 672.949
D25: 10.5 | E25: 3.88118 | F25: 22.3804 | G25: 721.89 | I25: 10.5 | J25: 3.86636 | K25: -20.8747 | L25: 719.133 | N25: 10.5 | O25: 3.64618 | P25: -21.1996 | Q25: 678.18
D26: 11 | E26: 3.90434 | F26: 23.4721 | G26: 726.197 | I26: 11 | J26: 3.8936 | K26: -21.8945 | L26: 724.201 | N26: 11 | O26: 3.66679 | P26: -22.2431 | Q26: 682.013
D27: 11.5 | E27: 3.92018 | F27: 24.564 | G27: 729.144 | I27: 11.5 | J27: 3.91312 | K27: -22.9158 | L27: 727.831 | N27: 11.5 | O27: 3.6815 | P27: -23.2886 | Q27: 684.75
D28: 12 | E28: 3.92952 | F28: 25.6569 | G28: 730.881 | I28: 12 | J28: 3.92541 | K28: -23.9391 | L28: 730.116 | N28: 12 | O28: 3.69121 | P28: -24.3358 | Q28: 686.556
D29: 12.5 | E29: 3.9331 | F29: 26.7517 | G29: 731.546 | I29: 12.5 | J29: 3.93196 | K29: -24.9642 | L29: 731.334 | N29: 12.5 | O29: 3.69571 | P29: -25.3849 | Q29: 687.392
D30: 13 | E30: 3.93142 | F30: 27.8479 | G30: 731.233 | I30: 13 | J30: 3.93397 | K30: -25.9911 | L30: 731.707 | N30: 13 | O30: 3.69595 | P30: -26.436 | Q30: 687.437
D31: 13.5 | E31: 3.92528 | F31: 28.9457 | G31: 730.092 | I31: 13.5 | J31: 3.9312 | K31: -27.0195 | L31: 731.194 | N31: 13.5 | O31: 3.69276 | P31: -27.4889 | Q31: 686.843
D32: 14 | E32: 3.91534 | F32: 30.0452 | G32: 728.244 | I32: 14 | J32: 3.92391 | K32: -28.0502 | L32: 729.837 | N32: 14 | O32: 3.68642 | P32: -28.5437 | Q32: 685.665
D33: 14.5 | E33: 3.90227 | F33: 31.1465 | G33: 725.812 | I33: 14.5 | J33: 3.91308 | K33: -29.0829 | L33: 727.823 | N33: 14.5 | O33: 3.67765 | P33: -29.6004 | Q33: 684.033
D34: 15 | E34: 3.88657 | F34: 32.25 | G34: 722.892 | I34: 15 | J34: 3.8997 | K34: -30.1176 | L34: 725.334 | N34: 15 | O34: 3.66651 | P34: -30.6591 | Q34: 681.962
D35: 15.5 | E35: 3.86724 | F35: 33.3568 | G35: 719.297 | I35: 15.5 | J35: 3.88421 | K35: -31.1541 | L35: 722.454 | N35: 15.5 | O35: 3.65317 | P35: -31.7196 | Q35: 679.48
... D49: 22.5 | E49: 3.51366 | F49: 49.0474 | G49: 653.532 | I49: 22.5 | J49: 3.57077 | K49: -45.8082 | L49: 664.155 | N49: 22.5 | O49: 3.39939 | P49: -46.6258 | Q49: 632.28
G50: =MAX(G4:G49) -> 731.546 | L50: =MAX(L4:L49) -> 731.707 | Q50: =MAX(Q4:Q49) -> 687.437

Sheet C2E30
A2: -0.001 | B2: -1 | D2: b/300 | F2: -0.001 | G2: -1 | I2: b/200 | N2: b/100
A3: x | B3: y | D3: X | E3: LPF | F3: U_37__37 | G3: RF_37__37 | I3: X | J3: LPF | K3: U_37__37 | L3: RF_37__37 | N3: X | O3: LPF | P3: U_37__37 | Q3: RF_37__37
A4: 0 | B4: 0 | D4: 0 | E4: 0 | F4: 0 | G4: 0 | I4: 0 | J4: 0 | K4: 0.0562398 | L4: -1.05643e-09 | N4: 0 | O4: 0 | P4: 0.111916 | Q4: -2.95413e-09
A5: 2.9924569 | B5: 82.205283 | D5: 0.5 | E5: 0.473931 | F5: 2.00278 | G5: 64.4499 | I5: 0.5 | J5: 0.473731 | K5: -1.93556 | L5: 64.4227 | N5: 0.5 | O5: 0.472496 | P5: -1.91561 | Q5: 64.2548
A6: 6.225507 | B6: 176.23817 | D6: 1 | E6: 0.900779 | F6: 4.04758 | G6: 122.497 | I6: 1 | J6: 0.900007 | K6: -3.93548 | L6: 122.392 | N6: 1 | O6: 0.895351 | P6: -3.95211 | Q6: 121.759
A7: 9.9689272 | B7: 263.58652 | D7: 1.5 | E7: 1.2871 | F7: 6.09892 | G7: 175.033 | I7: 1.5 | J7: 1.28542 | K7: -5.94215 | L7: 174.805 | N7: 1.5 | O7: 1.27552 | P7: -5.99601 | Q7: 173.457
A8: 13.335802 | B8: 332.73118 | D8: 2 | E8: 1.6383 | F8: 8.15569 | G8: 222.793 | I8: 2 | J8: 1.6354 | K8: -7.95443 | L8: 222.398 | N8: 2 | O8: 1.61864 | P8: -8.04601 | Q8: 220.119
A9: 16.840033 | B9: 392.16207 | D9: 2.5 | E9: 1.95886 | F9: 10.217 | G9: 266.385 | I9: 2.5 | J9: 1.95442 | K9: -9.97135 | L9: 265.781 | N9: 2.5 | O9: 1.92935 | P9: -10.101 | Q9: 262.372
A10: 20.155849 | B10: 441.88414 | D10: 3 | E10: 2.25249 | F10: 12.282 | G10: 306.317 | I10: 3 | J10: 2.24619 | K10: -11.9921 | L10: 305.459 | N10: 3 | O10: 2.21142 | P10: -12.1602 | Q10: 300.732
A11: 23.422303 | B11: 479.46735 | D11: 3.5 | E11: 2.52234 | F11: 14.35 | G11: 343.013 | I11: 3.5 | J11: 2.51382 | K11: -14.0158 | L11: 341.854 | N11: 3.5 | O11: 2.468 | P11: -14.2226 | Q11: 335.623
A12: 27.431677 | B12: 509.75552 | D12: 4 | E12: 2.77103 | F12: 16.4204 | G12: 376.833 | I12: 4 | J12: 2.7599 | K12: -16.042 | L12: 375.318 | N12: 4 | O12: 2.70058 | P12: -16.2881 | Q12: 367.251
A13: 31.903754 | B13: 528.50405 | D13: 4.5 | E13: 3.00074 | F13: 18.4926 | G13: 408.071 | I13: 4.5 | J13: 2.98589 | K13: -18.0701 | L13: 406.052 | N13: 4.5 | O13: 2.90841 | P13: -18.3563 | Q13: 395.515
A14: 36.698916 | B14: 535.71505 | D14: 5 | E14: 3.20939 | F14: 20.5669 | G14: 436.445 | I14: 5 | J14: 3.18874 | K14: -20.1009 | L14: 433.637 | N14: 5 | O14: 3.08687 | P14: -20.43 | Q14: 419.783
A15: 43.448979 | B15: 544.11034 | D15: 5.5 | E15: 3.38685 | F15: 22.6464 | G15: 460.578 | I15: 5.5 | J15: 3.36126 | K15: -22.1358 | L15: 457.098 | N15: 5.5 | O15: 3.23427 | P15: -22.5087 | Q15: 439.829
... A21: 70.213819 | B21: 466.01073 | D21: 8.5 | E21: 3.86214 | F21: 35.2329 | G21: 525.213 | I21: 8.5 | J21: 3.82608 | K21: -34.4557 | L21: 520.308 | N21: 8.5 | O21: 3.62646 | P21: -35.1038 | Q21: 493.162
D22: 9 | E22: 3.87639 | F22: 37.3466 | G22: 527.15 | I22: 9 | J22: 3.83832 | K22: -36.533 | L22: 521.974 | N22: 9 | O22: 3.6381 | P22: -37.2249 | Q22: 494.746
D23: 9.5 | E23: 3.87949 | F23: 39.4687 | G23: 527.572 | I23: 9.5 | J23: 3.84137 | K23: -38.6147 | L23: 522.388 | N23: 9.125 | O23: 3.63952 | P23: -37.7561 | Q23: 494.939
D24: 10 | E24: 3.87084 | F24: 41.6037 | G24: 526.396 | I24: 10 | J24: 3.8341 | K24: -40.7066 | L24: 521.399 | N24: 9.25 | O24: 3.64049 | P24: -38.2875 | Q24: 495.071
D25: 10.5 | E25: 3.85608 | F25: 43.7464 | G25: 524.388 | I25: 10.5 | J25: 3.82093 | K25: -42.8043 | L25: 519.608 | N25: 9.375 | O25: 3.64104 | P25: -38.8193 | Q25: 495.146
D26: 11 | E26: 3.83678 | F26: 45.8955 | G26: 521.763 | I26: 11 | J26: 3.80453 | K26: -44.9056 | L26: 517.378 | N26: 9.5 | O26: 3.64111 | P26: -39.3516 | Q26: 495.155
D27: 11.5 | E27: 3.81012 | F27: 48.063 | G27: 518.138 | I27: 11.5 | J27: 3.78335 | K27: -47.0157 | L27: 514.498 | N27: 9.625 | O27: 3.64077 | P27: -39.8842 | Q27: 495.108
D28: 12 | E28: 3.77706 | F28: 50.2514 | G28: 513.642 | I28: 12 | J28: 3.75567 | K28: -49.1457 | L28: 510.734 | N28: 9.75 | O28: 3.6401 | P28: -40.4171 | Q28: 495.017
D29: 12.5 | E29: 3.74046 | F29: 52.4521 | G29: 508.665 | I29: 12.5 | J29: 3.72497 | K29: -51.2851 | L29: 506.558 | N29: 9.875 | O29: 3.63911 | P29: -40.9501 | Q29: 494.882
D30: 13 | E30: 3.70155 | F30: 54.6632 | G30: 503.374 | I30: 13 | J30: 3.69154 | K30: -53.4338 | L30: 502.013 | N30: 10.0625 | O30: 3.63715 | P30: -41.7501 | Q30: 494.617
D31: 13.5 | E31: 3.65852 | F31: 56.8974 | G31: 497.522 | I31: 13.5 | J31: 3.65355 | K31: -55.6038 | L31: 496.846 | N31: 10.3438 | O31: 3.63328 | P31: -42.9503 | Q31: 494.089
D32: 14 | E32: 3.61284 | F32: 59.1481 | G32: 491.31 | I32: 14 | J32: 3.61352 | K32: -57.7862 | L32: 491.403 | N32: 10.7656 | O32: 3.62547 | P32: -44.7514 | Q32: 493.028
D33: 14.5 | E33: 3.56536 | F33: 61.414 | G33: 484.854 | I33: 14.5 | J33: 3.57137 | K33: -59.9814 | L33: 485.671 | N33: 11.2656 | O33: 3.61331 | P33: -46.887 | Q33: 491.375
... D41: 18.5 | E41: 3.15133 | F41: 79.9939 | G41: 428.549 | I41: 18.5 | J41: 3.18768 | K41: -78.0114 | L41: 433.493 | N41: 15.2656 | O41: 3.37743 | P41: -64.4288 | Q41: 459.296
G42: =MAX(G4:G41) -> 527.572 | L42: =MAX(L4:L41) -> 522.388 | Q42: =MAX(Q4:Q41) -> 495.155

Sheet C2E80
A2: -0.001 | B2: -1 | D2: b/300 | I2: b/200 | M2: -1 | N2: b/100
A3: x | B3: y | D3: X | E3: LPF | F3: U_38__38 | G3: RF_38__38 | I3: X | J3: LPF | K3: U_38__38 | L3: RF_38__38 | N3: X | O3: LPF | P3: U_38__38 | Q3: RF_38__38
A4: 0 | B4: 0 | D4: 0 | E4: 0 | F4: 0 | G4: 0 | I4: 0 | J4: 0 | K4: 0.0565232 | L4: 5.60507e-10 | N4: 0 | O4: 0 | P4: 0.112342 | Q4: -6.19879e-09
A5: 3.6813541 | B5: 42.741112 | D5: 0.5 | E5: 0.483864 | F5: 3.34569 | G5: 39.5909 | I5: 0.5 | J5: 0.483717 | K5: -3.29685 | L5: 39.579 | N5: 0.5 | O5: 0.482853 | P5: -3.31133 | Q5: 39.5082
A6: 6.7138437 | B6: 74.86505 | D6: 1 | E6: 0.937469 | F6: 6.72887 | G6: 76.7061 | I6: 1 | J6: 0.936864 | K6: -6.65386 | L6: 76.6566 | N6: 1 | O6: 0.933375 | P6: -6.73827 | Q6: 76.3711
A7: 11.05379 | B7: 125.78554 | D7: 1.5 | E7: 1.36349 | F7: 10.1148 | G7: 111.564 | I7: 1.5 | J7: 1.36205 | K7: -10.0135 | L7: 111.446 | N7: 1.5 | O7: 1.35399 | P7: -10.1673 | Q7: 110.787
A8: 15.438722 | B8: 170.02856 | D8: 2 | E8: 1.76426 | F8: 13.5025 | G8: 144.356 | I8: 2 | J8: 1.76152 | K8: -13.3748 | L8: 144.132 | N8: 2 | O8: 1.74668 | P8: -13.5975 | Q8: 142.918
A9: 21.221363 | B9: 220.92715 | D9: 2.5 | E9: 2.1418 | F9: 16.891 | G9: 175.248 | I9: 2.5 | J9: 2.13717 | K9: -16.7367 | L9: 174.868 | N9: 2.5 | O9: 2.11295 | P9: -17.0277 | Q9: 172.887
A10: 26.722371 | B10: 261.51135 | D10: 3 | E10: 2.49784 | F10: 20.2794 | G10: 204.38 | I10: 3 | J10: 2.49055 | K10: -20.0982 | L10: 203.783 | N10: 3 | O10: 2.45195 | P10: -20.4576 | Q10: 200.625
A11: 31.66181 | B11: 288.75051 | D11: 3.5 | E11: 2.83212 | F11: 23.667 | G11: 231.731 | I11: 3.5 | J11: 2.81841 | K11: -23.4596 | L11: 230.609 | N11: 3.5 | O11: 2.75404 | P11: -23.8891 | Q11: 225.342
A12: 37.111337 | B12: 308.09119 | D12: 4 | E12: 3.12176 | F12: 27.0597 | G12: 255.43 | I12: 4 | J12: 3.10049 | K12: -26.8242 | L12: 253.69 | N12: 4 | O12: 3.00624 | P12: -27.3232 | Q12: 245.978
A13: 42.931053 | B13: 318.32154 | D13: 4.5 | E13: 3.35363 | F13: 30.4604 | G13: 274.403 | I13: 4.5 | J13: 3.32842 | K13: -30.192 | L13: 272.34 | N13: 4.5 | O13: 3.20826 | P13: -30.7627 | Q13: 262.507
A14: 50.099398 | B14: 324.28257 | D14: 5 | E14: 3.53623 | F14: 33.86 | G14: 289.343 | I14: 5 | J14: 3.50581 | K14: -33.5652 | L14: 286.854 | N14: 5 | O14: 3.36601 | P14: -34.2078 | Q14: 275.415
A15: 56.103149 | B15: 325.40542 | D15: 5.5 | E15: 3.67768 | F15: 37.2617 | G15: 300.917 | I15: 5.5 | J15: 3.64059 | K15: -36.9447 | L15: 297.882 | N15: 5.5 | O15: 3.48516 | P15: -37.6615 | Q15: 285.165
... A18: 75.455264 | B18: 291.12087 | D18: 7 | E18: 3.905 | F18: 47.5251 | G18: 319.517 | I18: 7 | J18: 3.85172 | K18: -47.1534 | L18: 315.158 | N18: 7 | O18: 3.67753 | P18: -48.0945 | Q18: 300.905
D19: 7.125 | E19: 3.91047 | F19: 48.3989 | G19: 319.965 | I19: 7.5 | J19: 3.8634 | K19: -50.6438 | L19: 316.113 | N19: 7.5 | O19: 3.69518 | P19: -51.6416 | Q19: 302.349
D20: 7.25 | E20: 3.91346 | F20: 49.2793 | G20: 320.209 | I20: 8 | J20: 3.86039 | K20: -54.1602 | L20: 315.867 | N20: 8 | O20: 3.70115 | P20: -55.1974 | Q20: 302.838
D21: 7.375 | E21: 3.91483 | F21: 50.1637 | G21: 320.321 | I21: 8.5 | J21: 3.83826 | K21: -57.7363 | L21: 314.056 | N21: 8.5 | O21: 3.68925 | P21: -58.8094 | Q21: 301.864
D22: 7.5 | E22: 3.91498 | F22: 51.0497 | G22: 320.334 | I22: 9 | J22: 3.80774 | K22: -61.3374 | L22: 311.559 | N22: 9 | O22: 3.6689 | P22: -62.4481 | Q22: 300.198
D23: 7.625 | E23: 3.91401 | F23: 51.9375 | G23: 320.254 | I23: 9.5 | J23: 3.7695 | K23: -64.9839 | L23: 308.43 | N23: 9.5 | O23: 3.64199 | P23: -66.1141 | Q23: 297.996
D24: 7.75 | E24: 3.9124 | F24: 52.8257 | G24: 320.122 | I24: 10 | J24: 3.72499 | K24: -68.6679 | L24: 304.788 | N24: 10 | O24: 3.60581 | P24: -69.8272 | Q24: 295.037
D25: 7.875 | E25: 3.90978 | F25: 53.7165 | G25: 319.908 | I25: 10.5 | J25: 3.67637 | K25: -72.373 | L25: 300.81 | N25: 10.5 | O25: 3.56494 | P25: -73.5582 | Q25: 291.692
D26: 8 | E26: 3.90616 | F26: 54.6101 | G26: 319.612 | I26: 11 | J26: 3.62386 | K26: -76.1151 | L26: 296.514 | N26: 11 | O26: 3.52189 | P26: -77.3074 | Q26: 288.17
D27: 8.125 | E27: 3.90154 | F27: 55.5062 | G27: 319.234 | I27: 11.5 | J27: 3.56662 | K27: -79.9057 | L27: 291.83 | N27: 11.5 | O27: 3.47309 | P27: -81.1137 | Q27: 284.177
D28: 8.3125 | E28: 3.89149 | F28: 56.8633 | G28: 318.411 | I28: 12 | J28: 3.50593 | K28: -83.7355 | L28: 286.864 | N28: 12 | O28: 3.42027 | P28: -84.9645 | Q28: 279.855
D29: 8.59375 | E29: 3.87188 | F29: 58.9151 | G29: 316.807 | I29: 12.5 | J29: 3.4432 | K29: -87.5905 | L29: 281.731 | N29: 12.5 | O29: 3.364 | P29: -88.8479 | Q29: 275.251
D30: 9.01562 | E30: 3.83775 | F30: 62.0164 | G30: 314.014 | I30: 13 | J30: 3.3768 | K30: -91.4904 | L30: 276.298 | N30: 13 | O30: 3.30617 | P30: -92.7461 | Q30: 270.519
... D35: 11.5156 | E35: 3.56732 | F35: 80.8985 | G35: 291.887 | I35: 15.5 | J35: 2.94732 | K35: -111.047 | L35: 241.158 | N35: 15.5 | O35: 2.90821 | P35: -112.585 | Q35: 237.957
G36: =MAX(G4:G35) -> 320.334 | L36: =MAX(L4:L35) -> 316.113 | Q36: =MAX(Q4:Q35) -> 302.838

Sheet All
A1: 63 | C1: Pu_exp | D1: Pu_EF | G1: Pu_EF/Pu_exp
D2: b/300 | E2: b/200 | F2: b/100 | G2: b/300 | H2: b/200 | I2: b/100
A3: 33 | B3: C1E10 | C3: 268.48 | D3: ='C1E10'!$G$80 -> 269.036 | E3: ='C1E10'!L104 -> 273.757 | F3: ='C1E10'!Q80 -> 270.956 | G3: =D3/$C3 -> 1.0020709 | H3: =E3/C3 -> 1.0196551 | I3: =F3/C3 -> 1.0092223
A4: 34 | B4: C1E30 | C4: 202.03 | D4: ='C1E30'!G43 -> 202.938 | E4: ='C1E30'!L105 -> 204.729 | F4: ='C1E30'!Q80 -> 203.001 | G4: =D4/$C4 -> 1.0044944 | H4: =E4/C4 -> 1.0133594 | I4: =F4/C4 -> 1.0048062
B5: C1E60 | C5: 134.85 | D5: ='C1E60'!G80 -> 155.136 | E5: ='C1E60'!L80 -> 155.915 | F5: ='C1E60'!Q80 -> 154.732 | G5: =D5/$C5 -> 1.1504338 | H5: =E5/C5 -> 1.1562106 | I5: =F5/C5 -> 1.1474379
A6: 36 | B6: C2E10 | C6: 743.99 | D6: ='C2E10'!G50 -> 731.546 | E6: ='C2E10'!L50 -> 731.707 | F6: ='C2E10'!Q50 -> 687.437 | G6: =D6/$C6 -> 0.98327397 | H6: =E6/C6 -> 0.98349037 | I6: =F6/C6 -> 0.92398688
A7: 37 | B7: C2E30 | C7: 543.96 | D7: ='C2E30'!G42 -> 527.572 | E7: ='C2E30'!L42 -> 522.388 | F7: ='C2E30'!Q42 -> 495.155 | G7: =D7/$C7 -> 0.96987278 | H7: =E7/C7 -> 0.96034267 | I7: =F7/C7 -> 0.91027833
A8: 38 | B8: C2E80 | C8: 327.29 | D8: ='C2E80'!G36 -> 320.334 | E8: ='C2E80'!L36 -> 316.113 | F8: ='C2E80'!Q36 -> 302.838 | G8: =D8/$C8 -> 0.97874668 | H8: =E8/C8 -> 0.96584986 | I8: =F8/C8 -> 0.9252895
B9: Mean | G9: =AVERAGE(G6:G8) -> 0.97729781 | H9: =AVERAGE(H6:H8) -> 0.9698943 | I9: =AVERAGE(I6:I8) -> 0.91985157
B10: COV | G10: =_xlfn.STDEV.P(G6:G8)/G9 -> 0.0056954066 | H10: =_xlfn.STDEV.P(H6:H8)/H9 -> 0.010179735 | I10: =_xlfn.STDEV.P(I6:I8)/I9 -> 0.0073817993

Sheet All (2)
A1: 63 | C1: Pu_exp | D1: Pu_EF | E1: Pu_EF/Pu_exp
C2: b/300 | D2: b/200 | E2: b/100
A3: 33 | B3: C1E10 | C3: 268.48 | D3: ='C1E10'!$G$80 -> 269.036 | E3: =D3/$C3 -> 1.0020709
A4: 34 | B4: C1E30 | C4: 202.03 | D4: ='C1E30'!G43 -> 202.938 | E4: =D4/$C4 -> 1.0044944
A5: 35 | B5: C1E60 | C5: 134.85 | D5: ='C1E60'!G80 -> 155.136 | E5: =D5/$C5 -> 1.1504338
A6: 36 | B6: C2E10 | C6: 743.99 | D6: ='C2E10'!G50 -> 731.546 | E6: =D6/$C6 -> 0.98327397
A7: 37 | B7: C2E30 | C7: 543.96 | D7: ='C2E30'!G42 -> 527.572 | E7: =D7/$C7 -> 0.96987278
A8: 38 | B8: C2E80 | C8: 327.29 | D8: ='C2E80'!G36 -> 320.334 | E8: =D8/$C8 -> 0.97874668
B9: Mean | E9: =AVERAGE(E6:E8) -> 0.97729781
B10: COV | E10: =_xlfn.STDEV.P(E6:E8)/E9 -> 0.0056954066
