Workbook

Sheet C1L1
D1: -0.001 | F1: -1
D2: b/200 | I2: b/300 | N2: b/100
A3: U_7__7 | B3: RF_7__7 | D3: X | E3: LPF | F3: U_7__7 | G3: RF_7__7 | I3: X | J3: LPF | K3: U_7__7 | L3: RF_7__7 | N3: X | O3: LPF | P3: U_7__7 | Q3: RF_7__7
A4: 0 | B4: 0 | D4: 0 | E4: 0 | F4: 0 | G4: 0 | I4: 0 | J4: 0 | K4: 0.000347935 | L4: 6.42242e-10
A5: 0.0087455058 | B5: 73.155184 | D5: 0.5 | E5: 0.487517 | F5: 0.144598 | G5: 127.537 | I5: 0.5 | J5: 0.487572 | K5: -0.147337 | L5: 127.552 | N5: 0 | O5: 0 | P5: 0.00773195 | Q5: -4.8063e-10
A6: 0.12390438 | B6: 189.57536 | D6: 1 | E6: 0.94249 | F6: 0.316554 | G6: 246.561 | I6: 1 | J6: 0.942743 | K6: -0.319963 | L6: 246.627 | N6: 0.5 | O6: 0.487211 | P6: -0.137477 | Q6: 127.457
A7: 0.18754251 | B7: 246.3162 | D7: 1.5 | E7: 1.35571 | F7: 0.513919 | G7: 354.654 | I7: 1.5 | J7: 1.35634 | K7: -0.517846 | L7: 354.819 | N7: 1 | O7: 0.941082 | P7: -0.308375 | Q7: 246.193
A8: 0.27344281 | B8: 306.03051 | D8: 2 | E8: 1.72054 | F8: 0.73448 | G8: 450.092 | I8: 2 | J8: 1.72173 | K8: -0.738768 | L8: 450.405 | N8: 1.5 | O8: 1.35223 | P8: -0.505375 | Q8: 353.744
A9: 0.51734525 | B9: 379.20124 | D9: 2.5 | E9: 2.03508 | F9: 0.974078 | G9: 532.377 | I9: 2.5 | J9: 2.03699 | K9: -0.978593 | L9: 532.877 | N9: 2 | O9: 1.71402 | P9: -0.726202 | Q9: 448.387
A10: 0.68312117 | B10: 452.36031 | D10: 3 | E10: 2.30221 | F10: 1.22799 | G10: 602.258 | I10: 3 | J10: 2.30492 | K10: -1.23263 | L10: 602.967 | N10: 2.5 | O10: 2.02477 | P10: -0.966551 | Q10: 529.681
A11: 0.92682927 | B11: 524.03848 | D11: 3.5 | E11: 2.52768 | F11: 1.49208 | G11: 661.242 | I11: 3.5 | J11: 2.53122 | K11: -1.49675 | L11: 662.167 | N11: 3 | O11: 2.28772 | P11: -1.22155 | Q11: 598.466
A12: 1.1680109 | B12: 576.31328 | D12: 4 | E12: 2.71813 | F12: 1.76318 | G12: 711.063 | I12: 4 | J12: 2.72248 | K12: -1.76782 | L12: 712.2 | N12: 3.5 | O12: 2.50892 | P12: -1.48693 | Q12: 656.334
A13: 1.4507822 | B13: 647.99728 | D13: 4.5 | E13: 2.87979 | F13: 2.03908 | G13: 753.354 | I13: 4.5 | J13: 2.88491 | K13: -2.04365 | L13: 754.692 | N13: 4 | O13: 2.69524 | P13: -1.75948 | Q13: 705.074
A14: 1.8103197 | B14: 709.24497 | D14: 5 | E14: 3.018 | F14: 2.3183 | G14: 789.509 | I14: 5 | J14: 3.02383 | K14: -2.32275 | L14: 791.034 | N14: 4.5 | O14: 2.85301 | P14: -2.03696 | Q14: 746.348
A15: 2.2472063 | B15: 764.53406 | D15: 5.5 | E15: 3.13709 | F15: 2.59983 | G15: 820.664 | I15: 5.5 | J15: 3.14359 | K15: -2.60412 | L15: 822.362 | N15: 5 | O15: 2.98728 | P15: -2.31792 | Q15: 781.472
A16: 2.5247303 | B16: 795.91876 | D16: 6 | E16: 3.2402 | F16: 2.88306 | G16: 847.635 | I16: 6 | J16: 3.24763 | K16: -2.8871 | L16: 849.579 | N16: 5.5 | O16: 3.10025 | P16: -2.60167 | Q16: 811.025
... A23: 8.5517442 | B23: 883.38548 | D23: 9.5 | E23: 3.54577 | F23: 4.9055 | G23: 927.572 | I23: 9.5 | J23: 3.55839 | K23: -4.90773 | L23: 930.875 | N23: 9 | O23: 3.45414 | P23: -4.63173 | Q23: 903.603
D24: 10 | E24: 3.54918 | F24: 5.19804 | G24: 928.466 | I24: 10 | J24: 3.56008 | K24: -5.19987 | L24: 931.316 | N24: 9.5 | O24: 3.4669 | P24: -4.92483 | Q24: 906.941
D25: 10.5 | E25: 3.54853 | F25: 5.49065 | G25: 928.296 | I25: 10.5 | J25: 3.55785 | K25: -5.49188 | L25: 930.734 | N25: 10 | O25: 3.47492 | P25: -5.21837 | Q25: 909.038
D26: 11 | E26: 3.54534 | F26: 5.7832 | G26: 927.462 | I26: 11 | J26: 3.55343 | K26: -5.784 | L26: 929.576 | N26: 10.5 | O26: 3.47904 | P26: -5.5123 | Q26: 910.116
D27: 11.5 | E27: 3.53979 | F27: 6.07599 | G27: 926.009 | I27: 11.5 | J27: 3.54708 | K27: -6.07604 | L27: 927.916 | N27: 11 | O27: 3.47972 | P27: -5.8065 | Q27: 910.296
D28: 12 | E28: 3.53261 | F28: 6.36887 | G28: 924.131 | I28: 12 | J28: 3.53897 | K28: -6.36801 | L28: 925.796 | N28: 11.5 | O28: 3.47749 | P28: -6.10111 | Q28: 909.711
D29: 12.5 | E29: 3.52402 | F29: 6.66177 | G29: 921.884 | I29: 12.5 | J29: 3.52981 | K29: -6.66014 | L29: 923.399 | N29: 12 | O29: 3.47268 | P29: -6.39616 | Q29: 908.453
D30: 13 | E30: 3.51417 | F30: 6.95465 | G30: 919.307 | I30: 13 | J30: 3.51973 | K30: -6.95247 | L30: 920.76 | N30: 12.5 | O30: 3.46604 | P30: -6.69139 | Q30: 906.717
D31: 13.5 | E31: 3.50344 | F31: 7.24756 | G31: 916.501 | I31: 13.5 | J31: 3.50854 | K31: -7.24486 | L31: 917.834 | N31: 13 | O31: 3.45811 | P31: -6.98693 | Q31: 904.641
D32: 14 | E32: 3.49193 | F32: 7.54074 | G32: 913.488 | I32: 14 | J32: 3.49645 | K32: -7.5373 | L32: 914.672 | N32: 13.5 | O32: 3.44914 | P32: -7.28245 | Q32: 902.295
D33: 14.5 | E33: 3.47971 | F33: 7.83408 | G33: 910.292 | I33: 14.5 | J33: 3.48377 | K33: -7.82992 | L33: 911.356 | N33: 14 | O33: 3.43942 | P33: -7.57809 | Q33: 899.752
D34: 15 | E34: 3.46718 | F34: 8.12737 | G34: 907.013 | I34: 15 | J34: 3.47074 | K34: -8.12263 | L34: 907.947 | N34: 14.5 | O34: 3.42909 | P34: -7.87376 | Q34: 897.05
D35: 15.5 | E35: 3.45433 | F35: 8.42063 | G35: 903.654 | I35: 15.5 | J35: 3.45747 | K35: -8.41537 | L35: 904.473 | N35: 15 | O35: 3.41807 | P35: -8.16946 | Q35: 894.168
... D79: 37.5 | E79: 2.95772 | F79: 21.3013 | G79: 773.74 | I79: 37.5 | J79: 2.95984 | K79: -21.2698 | L79: 774.294 | N79: 37 | O79: 2.92923 | P79: -21.1655 | Q79: 766.288
G80: =MAX(G4:G79) -> 928.466 | I80: 38 | J80: 2.95128 | K80: -21.5614 | L80: 772.055 | N80: 37.5 | O80: 2.92048 | P80: -21.4602 | Q80: 763.998
I81: 38.5 | J81: 2.94282 | K81: -21.853 | L81: 769.842 | N81: 38 | O81: 2.91182 | P81: -21.7548 | Q81: 761.732
I82: 39 | J82: 2.93445 | K82: -22.1445 | L82: 767.651 | N82: 38.5 | O82: 2.90325 | P82: -22.0494 | Q82: 759.489
I83: 39.5 | J83: 2.92617 | K83: -22.4359 | L83: 765.486 | N83: 39 | O83: 2.89476 | P83: -22.344 | Q83: 757.269
I84: 40 | J84: 2.91799 | K84: -22.7274 | L84: 763.346 | N84: 39.5 | O84: 2.88635 | P84: -22.6385 | Q84: 755.069
I85: 40.5 | J85: 2.9099 | K85: -23.0188 | L85: 761.23 | N85: 40 | O85: 2.87802 | P85: -22.933 | Q85: 752.89
I86: 41 | J86: 2.90191 | K86: -23.3101 | L86: 759.139 | N86: 40.5 | O86: 2.86977 | P86: -23.2274 | Q86: 750.731
I87: 41.5 | J87: 2.89401 | K87: -23.6015 | L87: 757.072 | N87: 41 | O87: 2.86159 | P87: -23.5219 | Q87: 748.592
I88: 42 | J88: 2.88619 | K88: -23.8928 | L88: 755.026 | N88: 41.5 | O88: 2.8535 | P88: -23.8163 | Q88: 746.476
I89: 42.5 | J89: 2.87845 | K89: -24.184 | L89: 753.002 | N89: 42 | O89: 2.84548 | P89: -24.1108 | Q89: 744.378
...

Sheet C1L2
A2: -0.001 | B2: -1 | D2: b/200 | I2: b/300 | N2: b/100
A3: U_8__8 | B3: RF_8__8 | D3: X | E3: LPF | F3: U_8__8 | G3: RF_8__8 | I3: X | J3: LPF | K3: U_8__8 | L3: RF_8__8 | N3: X | O3: LPF | P3: U_8__8 | Q3: RF_8__8
A4: 0 | B4: 0 | D4: 0 | E4: 0 | F4: 0 | G4: 0 | I4: 0 | J4: 0 | K4: 0.00864851 | L4: -4.68587e-09 | N4: 0 | O4: 0 | P4: 0.0301774 | Q4: -1.43266e-08
A5: 0.00058303372 | B5: 10.467399 | D5: 0.5 | E5: 0.487121 | F5: 0.116091 | G5: 91.3482 | I5: 0.5 | J5: 0.487166 | K5: -0.123264 | L5: 91.3566 | N5: 0.5 | O5: 0.486852 | P5: -0.0956437 | Q5: 91.298
A6: 0.0089398504 | B6: 74.64775 | D6: 1 | E6: 0.938176 | F6: 0.275469 | G6: 175.934 | I6: 1 | J6: 0.938397 | K6: -0.284162 | L6: 175.975 | N6: 1 | O6: 0.936878 | P6: -0.251503 | Q6: 175.691
A7: 0.052473035 | B7: 108.98261 | D7: 1.5 | E7: 1.33981 | F7: 0.465068 | G7: 251.245 | I7: 1.5 | J7: 1.34038 | K7: -0.475023 | L7: 251.362 | N7: 1.5 | O7: 1.3365 | P7: -0.438616 | Q7: 250.625
A8: 0.13837334 | B8: 168.69692 | D8: 2 | E8: 1.68293 | F8: 0.681556 | G8: 315.587 | I8: 2 | J8: 1.68402 | K8: -0.692496 | L8: 315.793 | N8: 2 | O8: 1.67669 | P8: -0.653594 | Q8: 314.419
A9: 0.2219415 | B9: 210.50044 | D9: 2.5 | E9: 1.96689 | F9: 0.9186 | G9: 368.837 | I9: 2.5 | J9: 1.96862 | K9: -0.930273 | L9: 369.161 | N9: 2.5 | O9: 1.9572 | P9: -0.889903 | Q9: 367.021
A10: 0.22621708 | B10: 243.3369 | D10: 3 | E10: 2.19829 | F10: 1.16971 | G10: 412.23 | I10: 3 | J10: 2.20068 | K10: -1.18191 | L10: 412.678 | N10: 3 | O10: 2.18506 | P10: -1.14085 | Q10: 409.749
A11: 0.30939656 | B11: 282.15528 | D11: 3.5 | E11: 2.38659 | F11: 1.4299 | G11: 447.54 | I11: 3.5 | J11: 2.38961 | K11: -1.44246 | L11: 448.106 | N11: 3.5 | O11: 2.37001 | P11: -1.40131 | Q11: 444.43
A12: 0.50976581 | B12: 320.99116 | D12: 4 | E12: 2.54089 | F12: 1.69587 | G12: 476.474 | I12: 4 | J12: 2.54449 | K12: -1.70867 | L12: 477.15 | N12: 4 | O12: 2.52127 | P12: -1.66788 | Q12: 472.797
A13: 0.51287533 | B13: 344.87222 | D13: 4.5 | E13: 2.6687 | F13: 1.96556 | G13: 500.443 | I13: 4.5 | J13: 2.67282 | K13: -1.97849 | L13: 501.216 | N13: 4.5 | O13: 2.6464 | P13: -1.93844 | Q13: 496.261
A14: 0.78942766 | B14: 368.79409 | D14: 5 | E14: 2.77586 | F14: 2.2377 | G14: 520.536 | I14: 5 | J14: 2.78044 | K14: -2.25068 | L14: 521.407 | N14: 5 | O14: 2.75119 | P14: -2.21164 | Q14: 515.91
A15: 0.98901953 | B15: 401.6597 | D15: 5.5 | E15: 2.86674 | F15: 2.51148 | G15: 537.589 | I15: 5.5 | J15: 2.87173 | K15: -2.52445 | L15: 538.525 | N15: 5.5 | O15: 2.83998 | P15: -2.48667 | Q15: 532.562
... A27: 17.655233 | B27: 598.17705 | D27: 11.5 | E27: 3.38729 | F27: 5.83681 | G27: 635.197 | I27: 11.5 | J27: 3.39494 | K27: -5.84723 | L27: 636.631 | N27: 11.5 | O27: 3.34704 | P27: -5.83327 | Q27: 627.651
D28: 12 | E28: 3.40872 | F28: 6.11496 | G28: 639.215 | I28: 12 | J28: 3.41649 | K28: -6.12507 | L28: 640.672 | N28: 12 | O28: 3.36748 | P28: -6.11352 | Q28: 631.482
D29: 12.5 | E29: 3.42853 | F29: 6.39316 | G29: 642.931 | I29: 12.5 | J29: 3.43642 | K29: -6.40296 | L29: 644.409 | N29: 12.5 | O29: 3.38616 | P29: -6.39387 | Q29: 634.985
D30: 13 | E30: 3.44691 | F30: 6.6714 | G30: 646.377 | I30: 13 | J30: 3.4549 | K30: -6.68087 | L30: 647.875 | N30: 13 | O30: 3.40326 | P30: -6.6743 | Q30: 638.191
D31: 13.5 | E31: 3.464 | F31: 6.94967 | G31: 649.581 | I31: 13.5 | J31: 3.4721 | K31: -6.95882 | L31: 651.099 | N31: 13.5 | O31: 3.41879 | P31: -6.95481 | Q31: 641.105
D32: 14 | E32: 3.47981 | F32: 7.22799 | G32: 652.546 | I32: 14 | J32: 3.48813 | K32: -7.2368 | L32: 654.106 | N32: 14 | O32: 3.43304 | P32: -7.23538 | Q32: 643.775
D33: 14.5 | E33: 3.4944 | F33: 7.50637 | G33: 655.281 | I33: 14.5 | J33: 3.50311 | K33: -7.51479 | L33: 656.915 | N33: 14.5 | O33: 3.44542 | P33: -7.51621 | Q33: 646.096
D34: 15 | E34: 3.50787 | F34: 7.7848 | G34: 657.808 | I34: 15 | J34: 3.51707 | K34: -7.79281 | L34: 659.533 | N34: 15 | O34: 3.45632 | P34: -7.79726 | Q34: 648.141
D35: 15.5 | E35: 3.52025 | F35: 8.0633 | G35: 660.13 | I35: 15.5 | J35: 3.52997 | K35: -8.07088 | L35: 661.952 | N35: 15.5 | O35: 3.46587 | P35: -8.07845 | Q35: 649.94
D36: 16 | E36: 3.53076 | F36: 8.34212 | G36: 662.111 | I36: 16 | J36: 3.54186 | K36: -8.34902 | L36: 664.182 | N36: 16 | O36: 3.47402 | P36: -8.35974 | Q36: 651.459
D37: 16.5 | E37: 3.53989 | F37: 8.62111 | G37: 663.816 | I37: 16.5 | J37: 3.55209 | K37: -8.62743 | L37: 666.109 | N37: 16.5 | O37: 3.48045 | P37: -8.64137 | Q37: 652.664
D38: 17 | E38: 3.5476 | F38: 8.90023 | G38: 665.266 | I38: 17 | J38: 3.56092 | K38: -8.90606 | L38: 667.76 | N38: 17 | O38: 3.48583 | P38: -8.92302 | Q38: 653.672
D39: 17.5 | E39: 3.55396 | F39: 9.17959 | G39: 666.463 | I39: 17.5 | J39: 3.56802 | K39: -9.18497 | L39: 669.086 | N39: 17.5 | O39: 3.49009 | P39: -9.2048 | Q39: 654.472
... D54: 25 | E54: 3.50867 | F54: 13.4022 | G54: 657.955 | I54: 25 | J54: 3.51954 | K54: -13.4043 | L54: 659.995 | N54: 25 | O54: 3.45179 | P54: -13.4531 | Q54: 647.289
D55: 25.5 | E55: 3.50081 | F55: 13.6847 | G55: 656.482 | L55: =MAX(L4:L54) -> 671.05 | Q55: =MAX(Q4:Q54) -> 655.744
D56: 26 | E56: 3.49243 | F56: 13.9674 | G56: 654.911
D57: 26.5 | E57: 3.48354 | F57: 14.2504 | G57: 653.243
D58: 27 | E58: 3.4745 | F58: 14.5334 | G58: 651.548
D59: 27.5 | E59: 3.46548 | F59: 14.8164 | G59: 649.857
D60: 28 | E60: 3.45645 | F60: 15.0994 | G60: 648.164
D61: 28.5 | E61: 3.44722 | F61: 15.3826 | G61: 646.432
D62: 29 | E62: 3.43771 | F62: 15.6659 | G62: 644.649
D63: 29.5 | E63: 3.42794 | F63: 15.9493 | G63: 642.816
D64: 30 | E64: 3.41809 | F64: 16.2328 | G64: 640.97
D65: 30.5 | E65: 3.40821 | F65: 16.5162 | G65: 639.118
D66: 31 | E66: 3.39832 | F66: 16.7996 | G66: 637.264
...

Sheet C1L3
A2: -0.001 | C2: -1 | D2: b/200 | I2: b/300 | N2: b/100
A3: U_9__9 | B3: RF_9__9 | D3: X | E3: LPF | F3: U_9__9 | G3: RF_9__9 | I3: X | J3: LPF | K3: U_9__9 | L3: RF_9__9 | N3: X | O3: LPF | P3: U_9__9 | Q3: RF_9__9
A4: 0.32211294 | B4: 10.491634 | D4: 0 | E4: 0 | F4: 0.0158957 | G4: -2.11619e-08 | I4: 0 | J4: 0 | K4: -0.0124191 | L4: 4.98778e-05 | N4: 0 | O4: 0 | P4: -0.0262188 | Q4: 1.29573e-06
A5: 1.0915336 | B5: 71.059218 | D5: 0.5 | E5: 0.451716 | F5: 0.409414 | G5: 44.5508 | I5: 0.5 | J5: 0.451807 | K5: -0.404676 | L5: 44.5598 | N5: 0.5 | O5: 0.451253 | P5: -0.42491 | Q5: 44.5052
A6: 2.4836494 | B6: 151.80889 | D6: 1 | E6: 0.817796 | F6: 0.81592 | G6: 80.6557 | I6: 1 | J6: 0.818113 | K6: -0.81 | L6: 80.687 | N6: 1 | O6: 0.816172 | P6: -0.836419 | Q6: 80.4955
A7: 4.6413143 | B7: 220.1165 | D7: 1.5 | E7: 1.1166 | F7: 1.23037 | G7: 110.126 | I7: 1.5 | J7: 1.11722 | K7: -1.22335 | L7: 110.186 | N7: 1.5 | O7: 1.11346 | P7: -1.25567 | Q7: 109.816
A8: 7.0695959 | B8: 265.1179 | D8: 2 | E8: 1.36325 | F8: 1.6497 | G8: 134.451 | I8: 2 | J8: 1.36419 | K8: -1.64164 | L8: 134.544 | N8: 2 | O8: 1.35846 | P8: -1.6796 | Q8: 133.979
A9: 9.2049793 | B9: 296.92109 | D9: 2.5 | E9: 1.56938 | F9: 2.07208 | G9: 154.781 | I9: 2.5 | J9: 1.57064 | K9: -2.06304 | L9: 154.906 | N9: 2.5 | O9: 1.56293 | P9: -2.10642 | Q9: 154.145
A10: 12.554464 | B10: 317.82693 | D10: 3 | E10: 1.74375 | F10: 2.49641 | G10: 171.978 | I10: 3 | J10: 1.74533 | K10: -2.48644 | L10: 172.134 | N10: 3 | O10: 1.7357 | P10: -2.53505 | Q10: 171.184
A11: 17.772429 | B11: 333.25959 | D11: 3.5 | E11: 1.89292 | F11: 2.92201 | G11: 186.691 | I11: 3.5 | J11: 1.8948 | K11: -2.91115 | L11: 186.876 | N11: 3.5 | O11: 1.88336 | P11: -2.96485 | Q11: 185.748
A12: 25.591317 | B12: 343.20485 | D12: 4 | E12: 2.02187 | F12: 3.34847 | G12: 199.417 | I12: 4 | J12: 2.02402 | K12: -3.33675 | L12: 199.63 | N12: 4 | O12: 2.01089 | P12: -3.39541 | Q12: 198.325
A13: 33.404517 | B13: 343.82984 | D13: 4.5 | E13: 2.13435 | F13: 3.77551 | G13: 210.509 | I13: 4.5 | J13: 2.13677 | K13: -3.76295 | L13: 210.748 | N13: 4.5 | O13: 2.12206 | P13: -3.82647 | Q13: 209.289
A14: 41.536135 | B14: 332.79816 | D14: 5 | E14: 2.23329 | F14: 4.20296 | G14: 220.267 | I14: 5 | J14: 2.23595 | K14: -4.18958 | L14: 220.529 | N14: 5 | O14: 2.21978 | P14: -4.25788 | Q14: 218.927
A15: 48.609781 | B15: 321.78702 | D15: 5.5 | E15: 2.32097 | F15: 4.63069 | G15: 228.913 | I15: 5.5 | J15: 2.32385 | K15: -4.6165 | L15: 229.197 | N15: 5.5 | O15: 2.30633 | P15: -4.68952 | Q15: 227.469
A16: 61.291237 | B16: 298.23981 | D16: 6 | E16: 2.39918 | F16: 5.05862 | G16: 236.626 | I16: 6 | J16: 2.40227 | K16: -5.04365 | L16: 236.931 | N16: 6 | O16: 2.3835 | P16: -5.12131 | Q16: 235.08
D17: 6.5 | E17: 2.46938 | F17: 5.4867 | G17: 243.549 | I17: 6.5 | J17: 2.47266 | K17: -5.47095 | L17: 243.872 | N17: 6.5 | O17: 2.45273 | P17: -5.55322 | Q17: 241.907
D18: 7 | E18: 2.53272 | F18: 5.91488 | G18: 249.796 | I18: 7 | J18: 2.53618 | K18: -5.89837 | L18: 250.137 | N18: 7 | O18: 2.51517 | P18: -5.9852 | Q18: 248.065
D19: 7.5 | E19: 2.59016 | F19: 6.34313 | G19: 255.46 | I19: 7.5 | J19: 2.59379 | K19: -6.32587 | L19: 255.818 | N19: 7.5 | O19: 2.57177 | P19: -6.41723 | Q19: 253.647
D20: 8 | E20: 2.64249 | F20: 6.77145 | G20: 260.62 | I20: 8 | J20: 2.64627 | K20: -6.75344 | L20: 260.993 | N20: 8 | O20: 2.62332 | P20: -6.84929 | Q20: 258.73
D21: 8.5 | E21: 2.69035 | F21: 7.1998 | G21: 265.34 | I21: 8.5 | J21: 2.69427 | K21: -7.18105 | L21: 265.727 | N21: 8.5 | O21: 2.67045 | P21: -7.28137 | Q21: 263.378
D22: 9 | E22: 2.73429 | F22: 7.62818 | G22: 269.674 | I22: 9 | J22: 2.73835 | K22: -7.60869 | L22: 270.074 | N22: 9 | O22: 2.71371 | P22: -7.71346 | Q22: 267.645
D23: 9.5 | E23: 2.77477 | F23: 8.05658 | G23: 273.666 | I23: 9.5 | J23: 2.77896 | K23: -8.03637 | L23: 274.079 | N23: 9.5 | O23: 2.75356 | P23: -8.14556 | Q23: 271.574
D24: 10 | E24: 2.81219 | F24: 8.485 | G24: 277.357 | I24: 10 | J24: 2.8165 | K24: -8.46406 | L24: 277.781 | N24: 10 | O24: 2.79038 | P24: -8.57765 | Q24: 275.206
D25: 10.5 | E25: 2.84688 | F25: 8.91342 | G25: 280.778 | I25: 10.5 | J25: 2.8513 | K25: -8.89176 | L25: 281.214 | N25: 10.5 | O25: 2.8245 | P25: -9.00975 | Q25: 278.571
D26: 11 | E26: 2.87913 | F26: 9.34184 | G26: 283.958 | I26: 11 | J26: 2.88365 | K26: -9.31947 | L26: 284.404 | N26: 11 | O26: 2.85622 | P26: -9.44183 | Q26: 281.699
D27: 11.5 | E27: 2.90918 | F27: 9.77027 | G27: 286.922 | I27: 11.5 | J27: 2.9138 | K27: -9.74718 | L27: 287.378 | N27: 11.5 | O27: 2.88577 | P27: -9.87391 | Q27: 284.613
D28: 12 | E28: 2.93726 | F28: 10.1987 | G28: 289.691 | I28: 12 | J28: 2.94197 | K28: -10.1749 | L28: 290.156 | N28: 12 | O28: 2.91337 | P28: -10.306 | Q28: 287.335
... D104: 50 | E104: 3.32635 | F104: 42.9245 | G104: 328.064 | I104: 44.2798 | J104: 3.38814 | K104: -37.8778 | L104: 334.158 | N104: 50 | O104: 3.29069 | P104: -43.3076 | Q104: 324.546
D105: 50.5 | E105: 3.32091 | F105: 43.3597 | G105: 327.527 | L105: =MAX(L4:L104) -> 337.917 | Q105: =MAX(Q4:Q104) -> 332.981
D106: 51 | E106: 3.31542 | F106: 43.7949 | G106: 326.986
D107: 51.5 | E107: 3.30984 | F107: 44.23 | G107: 326.436
D108: 52 | E108: 3.3042 | F108: 44.6653 | G108: 325.879
D109: 52.5 | E109: 3.29848 | F109: 45.1007 | G109: 325.315
D110: 53 | E110: 3.2927 | F110: 45.5362 | G110: 324.745
D111: 53.5 | E111: 3.28685 | F111: 45.9719 | G111: 324.168
D112: 54 | E112: 3.28094 | F112: 46.4076 | G112: 323.585
D113: 54.5 | E113: 3.27498 | F113: 46.8434 | G113: 322.997
D114: 55 | E114: 3.26896 | F114: 47.2791 | G114: 322.404
D115: 55.5 | E115: 3.26293 | F115: 47.7148 | G115: 321.809
D116: 56 | E116: 3.25691 | F116: 48.1505 | G116: 321.215
...

Sheet C1L4
A2: Exp | B2: -0.001 | C2: -1 | D2: b/200 | I2: b/300 | N2: b/100
A3: U_10__10 | B3: RF_10__10 | D3: X | E3: LPF | F3: U_10__10 | G3: RF_10__10 | I3: X | J3: LPF | K3: U_10__10 | L3: RF_10__10 | N3: X | O3: LPF | P3: U_10__10 | Q3: RF_10__10
A4: 0.40065106 | B4: 5.8299144 | D4: 0 | E4: 0 | F4: 0 | G4: 0 | I4: 0 | J4: 0 | K4: -0.00396983 | L4: 4.79034e-10 | N4: 0 | O4: 0 | P4: -0.00423392 | Q4: -2.08444e-08
A5: 1.0773115 | B5: 47.758523 | D5: 0.5 | E5: 0.449558 | F5: 0.321422 | G5: 27.9112 | I5: 0.5 | J5: 0.44965 | K5: -0.320507 | L5: 27.9168 | N5: 0.5 | O5: 0.449115 | P5: -0.324025 | Q5: 27.8836
A6: 2.4580495 | B6: 109.86763 | D6: 1 | E6: 0.809493 | F6: 0.650983 | G6: 50.258 | I6: 1 | J6: 0.809809 | K6: -0.649462 | L6: 50.2776 | N6: 1 | O6: 0.807944 | P6: -0.656418 | Q6: 50.1618
A7: 5.5373915 | B7: 154.85639 | D7: 1.5 | E7: 1.09971 | F7: 0.98804 | G7: 68.2764 | I7: 1.5 | J7: 1.10031 | K7: -0.985903 | L7: 68.3138 | N7: 1.5 | O7: 1.09674 | P7: -0.996368 | Q7: 68.092
A8: 9.6235859 | B8: 182.73821 | D8: 2 | E8: 1.33662 | F8: 1.32963 | G8: 82.985 | I8: 2 | J8: 1.33753 | K8: -1.32688 | L8: 83.0413 | N8: 2 | O8: 1.33213 | P8: -1.34087 | Q8: 82.7062
A9: 16.552481 | B9: 201.24444 | D9: 2.5 | E9: 1.5327 | F9: 1.67403 | G9: 95.1585 | I9: 2.5 | J9: 1.5339 | K9: -1.67066 | L9: 95.2334 | N9: 2.5 | O9: 1.5267 | P9: -1.68818 | Q9: 94.7864
A10: 26.567276 | B10: 208.81697 | D10: 3 | E10: 1.69718 | F10: 2.02021 | G10: 105.371 | I10: 3 | J10: 1.69867 | K10: -2.01622 | L10: 105.463 | N10: 3 | O10: 1.68976 | P10: -2.03727 | Q10: 104.91
A11: 41.300363 | B11: 213.19109 | D11: 3.5 | E11: 1.8369 | F11: 2.36755 | G11: 114.045 | I11: 3.5 | J11: 1.83865 | K11: -2.36294 | L11: 114.154 | N11: 3.5 | O11: 1.82814 | P11: -2.38752 | Q11: 113.501
A12: 55.543732 | B12: 215.24461 | D12: 4 | E12: 1.95691 | F12: 2.71567 | G12: 121.496 | I12: 4 | J12: 1.95891 | K12: -2.71045 | L12: 121.625 | N12: 4 | O12: 1.94692 | P12: -2.73854 | Q12: 120.876
A13: 68.644901 | B13: 212.66012 | D13: 4.5 | E13: 2.06105 | F13: 3.06433 | G13: 127.965 | I13: 4.5 | J13: 2.06328 | K13: -3.05849 | L13: 128.103 | N13: 4.5 | O13: 2.04992 | P13: -3.09009 | Q13: 127.271
D14: 5 | E14: 2.15222 | F14: 3.41336 | G14: 133.625 | I14: 5 | J14: 2.15465 | K14: -3.40691 | L14: 133.776 | N14: 5 | O14: 2.14005 | P14: -3.44202 | Q14: 132.87
D15: 5.5 | E15: 2.23268 | F15: 3.76266 | G15: 138.62 | I15: 5.5 | J15: 2.2353 | K15: -3.7556 | L15: 138.783 | N15: 5.5 | O15: 2.21956 | P15: -3.79421 | Q15: 137.805
D16: 6 | E16: 2.3042 | F16: 4.11216 | G16: 143.06 | I16: 6 | J16: 2.30699 | K16: -4.10448 | L16: 143.234 | N16: 6 | O16: 2.29019 | P16: -4.1466 | Q16: 142.191
D17: 6.5 | E17: 2.36817 | F17: 4.4618 | G17: 147.032 | I17: 6.5 | J17: 2.37113 | K17: -4.45351 | L17: 147.215 | N17: 6.5 | O17: 2.35336 | P17: -4.49913 | Q17: 146.112
D18: 7 | E18: 2.42573 | F18: 4.81155 | G18: 150.605 | I18: 7 | J18: 2.42884 | K18: -4.80265 | L18: 150.798 | N18: 7 | O18: 2.41017 | P18: -4.85177 | Q18: 149.639
D19: 7.5 | E19: 2.47779 | F19: 5.16139 | G19: 153.837 | I19: 7.5 | J19: 2.48103 | K19: -5.15187 | L19: 154.038 | N19: 7.5 | O19: 2.46154 | P19: -5.20448 | Q19: 152.828
D20: 8 | E20: 2.5251 | F20: 5.51128 | G20: 156.774 | I20: 8 | J20: 2.52847 | K20: -5.50116 | L20: 156.983 | N20: 8 | O20: 2.50821 | P20: -5.55727 | Q20: 155.725
D21: 8.5 | E21: 2.56828 | F21: 5.86123 | G21: 159.455 | I21: 8.5 | J21: 2.57177 | K21: -5.85049 | L21: 159.671 | N21: 8.5 | O21: 2.55079 | P21: -5.9101 | Q21: 158.369
D22: 9 | E22: 2.60785 | F22: 6.21122 | G22: 161.911 | I22: 9 | J22: 2.61144 | K22: -6.19987 | L22: 162.134 | N22: 9 | O22: 2.5898 | P22: -6.26296 | Q22: 160.791
D23: 9.5 | E23: 2.64424 | F23: 6.56123 | G23: 164.17 | I23: 9.5 | J23: 2.64793 | K23: -6.54927 | L23: 164.4 | N23: 9.5 | O23: 2.62567 | P23: -6.61586 | Q23: 163.018
D24: 10 | E24: 2.67781 | F24: 6.91127 | G24: 166.255 | I24: 10 | J24: 2.6816 | K24: -6.89869 | L24: 166.49 | N24: 10 | O24: 2.65877 | P24: -6.96878 | Q24: 165.072
D25: 10.5 | E25: 2.70889 | F25: 7.26132 | G25: 168.184 | I25: 10.5 | J25: 2.71277 | K25: -7.24814 | L25: 168.425 | N25: 10.5 | O25: 2.68939 | P25: -7.32172 | Q25: 166.974
... D154: 75 | E154: 3.37219 | F154: 52.3818 | G154: 209.365 | I154: 75 | J154: 3.3797 | K154: -52.2873 | L154: 209.831 | N154: 75 | O154: 3.33503 | P154: -52.823 | Q154: 207.058
D155: 75.5 | E155: 3.37253 | F155: 52.7321 | G155: 209.386 | L155: =MAX(L4:L154) -> 209.831 | Q155: =MAX(Q4:Q154) -> 207.058
D156: 76 | E156: 3.37278 | F156: 53.0825 | G156: 209.402
D157: 76.5 | E157: 3.37293 | F157: 53.4331 | G157: 209.411
D158: 77 | E158: 3.37301 | F158: 53.7838 | G158: 209.416
D159: 77.5 | E159: 3.37302 | F159: 54.1346 | G159: 209.416
D160: 78 | E160: 3.37295 | F160: 54.4856 | G160: 209.412
D161: 78.5 | E161: 3.37281 | F161: 54.8366 | G161: 209.404
D162: 79 | E162: 3.37261 | F162: 55.1877 | G162: 209.391
D163: 79.5 | E163: 3.37236 | F163: 55.539 | G163: 209.376
D164: 80 | E164: 3.37204 | F164: 55.8903 | G164: 209.356
D165: 80.5 | E165: 3.37163 | F165: 56.2417 | G165: 209.33
D166: 81 | E166: 3.37114 | F166: 56.5932 | G166: 209.3
D167: 81.5 | E167: 3.37053 | F167: 56.9449 | G167: 209.262
... D195: 95.5 | E195: 3.33283 | F195: 66.8166 | G195: 206.921
G196: =MAX(G4:G195) -> 209.416

Sheet C2L1
B1: -0.001 | C1: -1
A2: exp | D2: b/200 | I2: b/300 | N2: b/100
A3: U_11__11 | B3: RF_11__11 | D3: X | E3: LPF | F3: U_11__11 | G3: RF_11__11 | I3: X | J3: LPF | K3: U_11__11 | L3: RF_11__11 | N3: X | O3: LPF | P3: U_11__11 | Q3: RF_11__11
A4: 0 | B4: 0 | D4: 0 | E4: 0 | F4: 0 | G4: 0 | I4: 0 | J4: 0 | K4: 0.018835 | L4: -6.80709e-09 | N4: 0 | O4: 0 | P4: 0.0714 | Q4: 2.16695e-09
A5: 0.083225802 | B5: 163.72834 | D5: 0.5 | E5: 0.492645 | F5: 0.120211 | G5: 219.134 | I5: 0.5 | J5: 0.493092 | K5: -0.141837 | L5: 219.333 | N5: 0.5 | O5: 0.490589 | P5: -0.0602432 | Q5: 218.22
A6: 0.35755998 | B6: 468.65455 | D6: 1 | E6: 0.965734 | F6: 0.299294 | G6: 429.57 | I6: 1 | J6: 0.967799 | K6: -0.329569 | L6: 430.488 | N6: 1 | O6: 0.956408 | P6: -0.219597 | Q6: 425.422
A7: 0.63777066 | B7: 608.7452 | D7: 1.5 | E7: 1.4118 | F7: 0.508825 | G7: 627.984 | I7: 1.5 | J7: 1.41713 | K7: -0.547891 | L7: 630.355 | N7: 1.5 | O7: 1.38837 | P7: -0.412429 | Q7: 617.567
A8: 0.98742186 | B8: 801.02888 | D8: 2 | E8: 1.82234 | F8: 0.751383 | G8: 810.603 | I8: 2 | J8: 1.83315 | K8: -0.79892 | L8: 815.411 | N8: 2 | O8: 1.77662 | P8: -0.643383 | Q8: 790.27
A9: 1.2322756 | B9: 932.88019 | D9: 2.5 | E9: 2.18952 | F9: 1.02722 | G9: 973.934 | I9: 2.5 | J9: 2.20852 | K9: -1.0824 | L9: 982.382 | N9: 2.5 | O9: 2.11323 | P9: -0.913972 | Q9: 939.983
A10: 1.6187529 | B10: 1092.1943 | D10: 3 | E10: 2.50834 | F10: 1.33384 | G10: 1115.73 | I10: 3 | J10: 2.53836 | K10: -1.39544 | L10: 1129.08 | N10: 3 | O10: 2.39305 | P10: -1.2233 | Q10: 1064.45
A11: 2.2194282 | B11: 1243.252 | D11: 3.5 | E11: 2.77525 | F11: 1.6682 | G11: 1234.46 | I11: 3.5 | J11: 2.82157 | K11: -1.73321 | L11: 1255.06 | N11: 3.5 | O11: 2.60491 | P11: -1.57336 | Q11: 1158.69
A12: 2.6792636 | B12: 1344.8687 | D12: 4 | E12: 2.97914 | F12: 2.03013 | G12: 1325.15 | I12: 4 | J12: 3.05116 | K12: -2.09375 | L12: 1357.18 | N12: 4 | O12: 2.76106 | P12: -1.95091 | Q12: 1228.14
A13: 3.1754353 | B13: 1427.2522 | D13: 4.5 | E13: 3.11457 | F13: 2.41739 | G13: 1385.39 | I13: 4.5 | J13: 3.21244 | K13: -2.47716 | L13: 1428.92 | N13: 4.5 | O13: 2.86533 | P13: -2.35279 | Q13: 1274.52
A14: 3.7438878 | B14: 1482.1582 | D14: 5 | E14: 3.19731 | F14: 2.81953 | G14: 1422.19 | I14: 5 | J14: 3.3071 | K14: -2.87667 | L14: 1471.03 | N14: 5 | O14: 2.93278 | P14: -2.76901 | Q14: 1304.53
A15: 4.5266364 | B15: 1526.0605 | D15: 5.5 | E15: 3.25038 | F15: 3.22837 | G15: 1445.8 | I15: 5.5 | J15: 3.36536 | K15: -3.28281 | L15: 1496.94 | N15: 5.5 | O15: 2.97791 | P15: -3.19243 | Q15: 1324.6
... A24: 27.278352 | B24: 1340.432 | D24: 10 | E24: 3.27576 | F24: 7.0289 | G24: 1457.08 | I24: 10 | J24: 3.3713 | K24: -7.04915 | L24: 1499.58 | N24: 10 | O24: 3.03907 | P24: -7.12048 | Q24: 1351.8
D25: 10.5 | E25: 3.26111 | F25: 7.45798 | G25: 1450.57 | I25: 10.5 | J25: 3.35433 | K25: -7.47369 | L25: 1492.03 | N25: 10.5 | O25: 3.03031 | P25: -7.56333 | Q25: 1347.91
D26: 11 | E26: 3.24552 | F26: 7.88764 | G26: 1443.64 | I26: 11 | J26: 3.33648 | K26: -7.89906 | L26: 1484.11 | N26: 11 | O26: 3.0202 | P26: -8.00694 | Q26: 1343.41
D27: 11.5 | E27: 3.22907 | F27: 8.31803 | G27: 1436.32 | I27: 11.5 | J27: 3.31782 | K27: -8.32519 | L27: 1475.8 | N27: 11.5 | O27: 3.00916 | P27: -8.45097 | Q27: 1338.5
D28: 12 | E28: 3.21218 | F28: 8.74913 | G28: 1428.81 | I28: 12 | J28: 3.29863 | K28: -8.75237 | L28: 1467.27 | N28: 12 | O28: 2.99733 | P28: -8.89546 | Q28: 1333.25
D29: 12.5 | E29: 3.19494 | F29: 9.18053 | G29: 1421.14 | I29: 12.5 | J29: 3.27894 | K29: -9.18047 | L29: 1458.51 | N29: 12.5 | O29: 2.98506 | P29: -9.34033 | Q29: 1327.79
D30: 13 | E30: 3.17732 | F30: 9.61253 | G30: 1413.31 | I30: 13 | J30: 3.25906 | K30: -9.60937 | L30: 1449.67 | N30: 13 | O30: 2.97234 | P30: -9.78549 | Q30: 1322.12
D31: 13.5 | E31: 3.15942 | F31: 10.0451 | G31: 1405.35 | I31: 13.5 | J31: 3.23904 | K31: -10.0388 | L31: 1440.76 | N31: 13.5 | O31: 2.9593 | P31: -10.2309 | Q31: 1316.32
D32: 14 | E32: 3.14146 | F32: 10.478 | G32: 1397.36 | I32: 14 | J32: 3.219 | K32: -10.4686 | L32: 1431.84 | N32: 14 | O32: 2.94609 | P32: -10.6764 | Q32: 1310.45
D33: 14.5 | E33: 3.12348 | F33: 10.9112 | G33: 1389.36 | I33: 14.5 | J33: 3.19894 | K33: -10.8988 | L33: 1422.92 | N33: 14.5 | O33: 2.93274 | P33: -11.1222 | Q33: 1304.51
D34: 15 | E34: 3.10554 | F34: 11.3449 | G34: 1381.38 | I34: 15 | J34: 3.17903 | K34: -11.3295 | L34: 1414.07 | N34: 15 | O34: 2.91919 | P34: -11.5681 | Q34: 1298.48
D35: 15.5 | E35: 3.0877 | F35: 11.7791 | G35: 1373.44 | I35: 15.5 | J35: 3.15929 | K35: -11.7607 | L35: 1405.28 | N35: 15.5 | O35: 2.90554 | P35: -12.0144 | Q35: 1292.41
D36: 16 | E36: 3.06997 | F36: 12.2136 | G36: 1365.55 | I36: 16 | J36: 3.13969 | K36: -12.1924 | L36: 1396.57 | N36: 16 | O36: 2.89185 | P36: -12.4609 | Q36: 1286.32
... D79: 37.5 | E79: 2.45347 | F79: 31.0826 | G79: 1091.34 | I79: 37.5 | J79: 2.48171 | K79: -30.9763 | L79: 1103.9 | N79: 37.5 | O79: 2.36666 | P79: -31.7954 | Q79: 1052.71
G80: =MAX(G4:G79) -> 1475.92 | L80: =MAX(L4:L79) -> 1524.56 | N80: 38 | O80: 2.35374 | P80: -32.2591 | Q80: 1046.98
N81: 38.5 | O81: 2.34073 | P81: -32.7237 | Q81: 1041.19
N82: 39 | O82: 2.32765 | P82: -33.1892 | Q82: 1035.37
N83: 39.5 | O83: 2.31449 | P83: -33.6559 | Q83: 1029.52
N84: 40 | O84: 2.30116 | P84: -34.1236 | Q84: 1023.58
N85: 40.5 | O85: 2.28771 | P85: -34.592 | Q85: 1017.6
N86: 41 | O86: 2.27416 | P86: -35.0612 | Q86: 1011.57
N87: 41.5 | O87: 2.26055 | P87: -35.5311 | Q87: 1005.52
N88: 42 | O88: 2.2469 | P88: -36.0021 | Q88: 999.447
N89: 42.5 | O89: 2.23316 | P89: -36.4743 | Q89: 993.331
N90: 43 | O90: 2.21932 | P90: -36.9477 | Q90: 987.174
...

Sheet C2L2
A2: -0.001 | B2: -1 | D2: b/200 | I2: b/300 | N2: b/100
A3: U_12__12 | B3: RF_12__12 | D3: X | E3: LPF | F3: U_12__12 | G3: RF_12__12 | I3: X | J3: LPF | K3: U_12__12 | L3: RF_12__12 | N3: X | O3: LPF | P3: U_12__12 | Q3: RF_12__12
A4: 0.18439905 | B4: 14.173228 | D4: 0 | E4: 0 | F4: 0 | G4: 0 | I4: 0 | J4: 0 | K4: 0.035001 | L4: -8.29579e-09 | N4: 0 | O4: 0 | P4: 0.108623 | Q4: 8.73462e-09
A5: 0.49386138 | B5: 292.91339 | D5: 0.5 | E5: 0.494228 | F5: 0.0627055 | G5: 153.594 | I5: 0.5 | J5: 0.494495 | K5: -0.0883096 | L5: 153.677 | N5: 0.5 | O5: 0.492971 | P5: 0.0117928 | Q5: 153.203
A6: 0.87722996 | B6: 485.03937 | D6: 1 | E6: 0.970168 | F6: 0.216929 | G6: 301.505 | I6: 1 | J6: 0.971415 | K6: -0.249758 | L6: 301.892 | N6: 1 | O6: 0.964302 | P6: -0.125705 | Q6: 299.682
A7: 1.2140921 | B7: 611.02362 | D7: 1.5 | E7: 1.4145 | F7: 0.421472 | G7: 439.596 | I7: 1.5 | J7: 1.41779 | K7: -0.460856 | L7: 440.617 | N7: 1.5 | O7: 1.39909 | P7: -0.318389 | Q7: 434.808
A8: 2.2480922 | B8: 790.55118 | D8: 2 | E8: 1.80891 | F8: 0.68488 | G8: 562.178 | I8: 2 | J8: 1.81565 | K8: -0.729596 | L8: 564.272 | N8: 2 | O8: 1.77748 | P8: -0.576538 | Q8: 552.395
A9: 3.6005352 | B9: 885.03937 | D9: 2.5 | E9: 2.13753 | F9: 1.00478 | G9: 664.288 | I9: 2.5 | J9: 2.14909 | K9: -1.05344 | L9: 667.882 | N9: 2.5 | O9: 2.08448 | P9: -0.896798 | Q9: 647.802
A10: 5.4819599 | B10: 973.22835 | D10: 3 | E10: 2.39743 | F10: 1.36791 | G10: 745.061 | I10: 3 | J10: 2.41447 | K10: -1.41939 | L10: 750.356 | N10: 3 | O10: 2.32098 | P10: -1.26341 | Q10: 721.301
A11: 8.0138786 | B11: 1047.2441 | D11: 3.5 | E11: 2.59838 | F11: 1.7591 | G11: 807.508 | I11: 3.5 | J11: 2.62076 | K11: -1.81254 | L11: 814.465 | N11: 3.5 | O11: 2.50015 | P11: -1.65963 | Q11: 776.983
A12: 10.419749 | B12: 1077.1654 | D12: 4 | E12: 2.75404 | F12: 2.16731 | G12: 855.885 | I12: 4 | J12: 2.78125 | K12: -2.22203 | L12: 864.341 | N12: 4 | O12: 2.63702 | P12: -2.07384 | Q12: 819.519
A13: 13.270523 | B13: 1070.8661 | D13: 4.5 | E13: 2.87636 | F13: 2.58581 | G13: 893.9 | I13: 4.5 | J13: 2.90779 | K13: -2.64129 | L13: 903.665 | N13: 4.5 | O13: 2.74353 | P13: -2.49911 | Q13: 852.619
A14: 16.687988 | B14: 1023.622 | D14: 5 | E14: 2.97422 | F14: 3.01074 | G14: 924.313 | I14: 5 | J14: 3.0093 | K14: -3.06653 | L14: 935.212 | N14: 5 | O14: 2.82813 | P14: -2.93144 | Q14: 878.91
A15: 18.315666 | B15: 1004.7244 | D15: 5.5 | E15: 3.05392 | F15: 3.43984 | G15: 949.1 | I15: 5.5 | J15: 3.09217 | K15: -3.4956 | L15: 960.985 | N15: 5.5 | O15: 2.89663 | P15: -3.36848 | Q15: 900.197
... A18: 25.963336 | B18: 888.18898 | D18: 7 | E18: 3.22233 | F18: 4.74092 | G18: 1001.43 | I18: 7 | J18: 3.26803 | K18: -4.79514 | L18: 1015.63 | N18: 7 | O18: 3.03809 | P18: -4.69634 | Q18: 944.181
D19: 7.5 | E19: 3.26277 | F19: 5.17725 | G19: 1014 | I19: 7.5 | J19: 3.31047 | K19: -5.23062 | L19: 1028.82 | N19: 7.5 | O19: 3.06991 | P19: -5.14259 | Q19: 954.064
D20: 8 | E20: 3.29781 | F20: 5.61436 | G20: 1024.88 | I20: 8 | J20: 3.34737 | K20: -5.66676 | L20: 1040.28 | N20: 8 | O20: 3.09645 | P20: -5.58996 | Q20: 962.313
D21: 8.5 | E21: 3.32786 | F21: 6.05213 | G21: 1034.22 | I21: 8.5 | J21: 3.37971 | K21: -6.10339 | L21: 1050.34 | N21: 8.5 | O21: 3.11878 | P21: -6.03809 | Q21: 969.25
D22: 9 | E22: 3.35374 | F22: 6.49043 | G22: 1042.26 | I22: 9 | J22: 3.40828 | K22: -6.5404 | L22: 1059.21 | N22: 9 | O22: 3.1377 | P22: -6.48689 | Q22: 975.13
D23: 9.5 | E23: 3.37595 | F23: 6.92911 | G23: 1049.17 | I23: 9.5 | J23: 3.43343 | K23: -6.97768 | L23: 1067.03 | N23: 9.5 | O23: 3.15374 | P23: -6.93618 | Q23: 980.113
D24: 10 | E24: 3.39505 | F24: 7.3681 | G24: 1055.1 | I24: 10 | J24: 3.45541 | K24: -7.41519 | L24: 1073.86 | N24: 10 | O24: 3.1674 | P24: -7.38584 | Q24: 984.356
D25: 10.5 | E25: 3.4116 | F25: 7.80733 | G25: 1060.25 | I25: 10.5 | J25: 3.47473 | K25: -7.85289 | L25: 1079.86 | N25: 10.5 | O25: 3.17839 | P25: -7.83605 | Q25: 987.762
D26: 11 | E26: 3.42535 | F26: 8.24686 | G26: 1064.51 | I26: 11 | J26: 3.49151 | K26: -8.29069 | L26: 1085.08 | N26: 11 | O26: 3.18691 | P26: -8.28694 | Q26: 990.41
D27: 11.5 | E27: 3.436 | F27: 8.68685 | G27: 1067.82 | I27: 11.5 | J27: 3.50597 | K27: -8.72858 | L27: 1089.58 | N27: 11.5 | O27: 3.19323 | P27: -8.7384 | Q27: 992.373
D28: 12 | E28: 3.44422 | F28: 9.12717 | G28: 1070.38 | I28: 12 | J28: 3.51721 | K28: -9.16685 | L28: 1093.06 | N28: 12 | O28: 3.19693 | P28: -9.19061 | Q28: 993.524
D29: 12.5 | E29: 3.44953 | F29: 9.5679 | G29: 1072.03 | I29: 12.5 | J29: 3.5261 | K29: -9.60532 | L29: 1095.82 | N29: 12.5 | O29: 3.19899 | P29: -9.64314 | Q29: 994.164
D30: 13 | E30: 3.4528 | F30: 10.0089 | G30: 1073.04 | I30: 13 | J30: 3.53244 | K30: -10.044 | L30: 1097.79 | N30: 13 | O30: 3.19958 | P30: -10.0959 | Q30: 994.366
... D79: 37.5 | E79: 2.8672 | F79: 31.9112 | G79: 891.051 | I79: 37.5 | J79: 2.93605 | K79: -31.8266 | L79: 912.472 | N79: 37.5 | O79: 2.694 | P79: -32.5504 | Q79: 837.225
G80: =MAX(G4:G79) -> 1073.49 | L80: =MAX(L4:L79) -> 1099.56 | N80: 38 | O80: 2.68257 | P80: -33.0128 | Q80: 833.675
N81: 38.5 | O81: 2.67127 | P81: -33.4752 | Q81: 830.162
N82: 39 | O82: 2.66008 | P82: -33.9376 | Q82: 826.684
N83: 39.5 | O83: 2.64897 | P83: -34.4001 | Q83: 823.233
N84: 40 | O84: 2.63797 | P84: -34.8626 | Q84: 819.815
N85: 40.5 | O85: 2.62709 | P85: -35.3251 | Q85: 816.432
N86: 41 | O86: 2.61629 | P86: -35.7876 | Q86: 813.076
N87: 41.5 | O87: 2.6056 | P87: -36.2503 | Q87: 809.752
N88: 42 | O88: 2.59501 | P88: -36.7129 | Q88: 806.461
N89: 42.5 | O89: 2.58451 | P89: -37.1755 | Q89: 803.2
N90: 43 | O90: 2.57415 | P90: -37.6381 | Q90: 799.98
N91: 43.5 | O91: 2.56391 | P91: -38.1007 | Q91: 796.798
...

Sheet C2L3
A2: -0.001 | B2: -1 | D2: b/200 | I2: b/300 | N2: b/100
A3: U_13__13 | B3: RF_13__13 | D3: X | E3: LPF | F3: U_13__13 | G3: RF_13__13 | I3: X | J3: LPF | K3: U_13__13 | L3: RF_13__13 | N3: X | O3: LPF | P3: U_13__13 | Q3: RF_13__13
A4: 0.017409104 | B4: 9.8867062 | D4: 0 | E4: 0 | F4: 0 | G4: 0 | I4: 0 | J4: 0 | K4: 0.0354038 | L4: -4.49632e-09 | N4: 0 | O4: 0 | P4: 0.106569 | Q4: 4.32183e-07
A5: 0.22631835 | B5: 149.98225 | D5: 0.5 | E5: 0.487009 | F5: 0.117551 | G5: 96.2968 | I5: 0.5 | J5: 0.487201 | K5: -0.139547 | L5: 96.3347 | N5: 0.5 | O5: 0.486093 | P5: -0.055353 | Q5: 96.1158
A6: 0.79212648 | B6: 279.06427 | D6: 1 | E6: 0.936604 | F6: 0.332712 | G6: 185.196 | I6: 1 | J6: 0.937506 | K6: -0.357993 | L6: 185.375 | N6: 1 | O6: 0.932249 | P6: -0.264459 | Q6: 184.336
A7: 1.5011251 | B7: 391.65293 | D7: 1.5 | E7: 1.33344 | F7: 0.594487 | G7: 263.667 | I7: 1.5 | J7: 1.3357 | K7: -0.622253 | L7: 264.114 | N7: 1.5 | O7: 1.32247 | P7: -0.523808 | Q7: 261.498
A8: 2.5671205 | B8: 490.48082 | D8: 2 | E8: 1.66726 | F8: 0.897675 | G8: 329.676 | I8: 2 | J8: 1.67145 | K8: -0.927127 | L8: 330.505 | N8: 2 | O8: 1.64685 | P8: -0.827677 | Q8: 325.629
A9: 4.2047027 | B9: 556.30241 | D9: 2.5 | E9: 1.93827 | F9: 1.23183 | G9: 383.251 | I9: 2.5 | J9: 1.94469 | K9: -1.26231 | L9: 384.536 | N9: 2.5 | O9: 1.90707 | P9: -1.16458 | Q9: 377.082
A10: 6.270681 | B10: 605.61107 | D10: 3 | E10: 2.15502 | F10: 1.58652 | G10: 426.11 | I10: 3 | J10: 2.16368 | K10: -1.61754 | L10: 427.836 | N10: 3 | O10: 2.11311 | P10: -1.52332 | Q10: 417.822
A11: 9.3353689 | B11: 641.11487 | D11: 3.5 | E11: 2.32862 | F11: 1.95416 | G11: 460.448 | I11: 3.5 | J11: 2.33936 | K11: -1.98533 | L11: 462.571 | N11: 3.5 | O11: 2.27688 | P11: -1.89586 | Q11: 450.204
A12: 14.7532 | B12: 670.96254 | D12: 4 | E12: 2.46908 | F12: 2.3299 | G12: 488.22 | I12: 4 | J12: 2.48167 | K12: -2.36092 | L12: 490.708 | N12: 4 | O12: 2.40864 | P12: -2.27713 | Q12: 476.268
A13: 20.029015 | B13: 684.33646 | D13: 4.5 | E13: 2.58427 | F13: 2.71081 | G13: 510.994 | I13: 4.5 | J13: 2.59849 | K13: -2.74144 | L13: 513.804 | N13: 4.5 | O13: 2.51622 | P13: -2.66407 | Q13: 497.539
A14: 25.733227 | B14: 681.19743 | D14: 5 | E14: 2.68007 | F14: 3.09512 | G14: 529.934 | I14: 5 | J14: 2.69571 | K14: -3.12516 | L14: 533.027 | N14: 5 | O14: 2.6054 | P14: -3.05481 | Q14: 515.169
A15: 31.223632 | B15: 675.32584 | D15: 5.5 | E15: 2.76079 | F15: 3.48173 | G15: 545.894 | I15: 5.5 | J15: 2.77769 | K15: -3.51105 | L15: 549.235 | N15: 5.5 | O15: 2.68034 | P15: -3.44819 | Q15: 529.986
... A17: 41.848475 | B17: 648.49721 | D17: 6.5 | E17: 2.889 | F17: 4.25936 | G17: 571.243 | I17: 6.5 | J17: 2.90799 | K17: -4.28685 | L17: 574.998 | N17: 6.5 | O17: 2.79897 | P17: -4.24009 | Q17: 553.442
D18: 7 | E18: 2.94068 | F18: 4.64961 | G18: 581.46 | I18: 7 | J18: 2.96055 | K18: -4.67606 | L18: 585.389 | N18: 7 | O18: 2.84665 | P18: -4.63778 | Q18: 562.868
D19: 7.5 | E19: 2.98604 | F19: 5.04051 | G19: 590.429 | I19: 7.5 | J19: 3.0067 | K19: -5.06584 | L19: 594.515 | N19: 7.5 | O19: 2.88844 | P19: -5.03627 | Q19: 571.13
D20: 8 | E20: 3.02618 | F20: 5.43191 | G20: 598.365 | I20: 8 | J20: 3.04756 | K20: -5.45606 | L20: 602.592 | N20: 8 | O20: 2.92535 | P20: -5.43539 | Q20: 578.428
D21: 8.5 | E21: 3.06193 | F21: 5.8237 | G21: 605.433 | I21: 8.5 | J21: 3.08396 | K21: -5.84663 | L21: 609.789 | N21: 8.5 | O21: 2.95817 | P21: -5.83501 | Q21: 584.918
D22: 9 | E22: 3.09396 | F22: 6.2158 | G22: 611.768 | I22: 9 | J22: 3.11659 | K22: -6.23746 | L22: 616.242 | N22: 9 | O22: 2.98755 | P22: -6.23504 | Q22: 590.726
D23: 9.5 | E23: 3.12284 | F23: 6.60815 | G23: 617.476 | I23: 9.5 | J23: 3.14601 | K23: -6.62851 | L23: 622.059 | N23: 9.5 | O23: 3.01398 | P23: -6.6354 | Q23: 595.952
D24: 10 | E24: 3.14898 | F24: 7.00071 | G24: 622.646 | I24: 10 | J24: 3.17267 | K24: -7.01972 | L24: 627.33 | N24: 10 | O24: 3.03788 | P24: -7.03604 | Q24: 600.677
D25: 10.5 | E25: 3.17277 | F25: 7.39343 | G25: 627.35 | I25: 10.5 | J25: 3.19693 | K25: -7.41108 | L25: 632.127 | N25: 10.5 | O25: 3.05959 | P25: -7.43691 | Q25: 604.969
D26: 11 | E26: 3.19451 | F26: 7.78629 | G26: 631.647 | I26: 11 | J26: 3.21911 | K26: -7.80256 | L26: 636.512 | N26: 11 | O26: 3.07938 | P26: -7.83797 | Q26: 608.884
D27: 11.5 | E27: 3.21444 | F27: 8.17927 | G27: 635.587 | I27: 11.5 | J27: 3.23945 | K27: -8.19413 | L27: 640.534 | N27: 11.5 | O27: 3.09751 | P27: -8.23919 | Q27: 612.467
D28: 12 | E28: 3.23277 | F28: 8.57234 | G28: 639.213 | I28: 12 | J28: 3.25818 | K28: -8.58578 | L28: 644.237 | N28: 12 | O28: 3.11415 | P28: -8.64056 | Q28: 615.758
D29: 12.5 | E29: 3.2497 | F29: 8.9655 | G29: 642.56 | I29: 12.5 | J29: 3.27548 | K29: -8.9775 | L29: 647.657 | N29: 12.5 | O29: 3.12949 | P29: -9.04204 | Q29: 618.79
... D104: 50 | E104: 3.38255 | F104: 38.5716 | G104: 668.826 | I104: 50 | J104: 3.44067 | K104: -38.464 | L104: 680.319 | N104: 50 | O104: 3.1834 | P104: -39.3314 | Q104: 629.45
D105: 50.5 | E105: 3.37662 | F105: 38.9699 | G105: 667.655 | L105: =MAX(L4:L104) -> 699.319 | Q105: =MAX(Q4:Q104) -> 656.575
D106: 51 | E106: 3.37059 | F106: 39.3683 | G106: 666.461
D107: 51.5 | E107: 3.36443 | F107: 39.7669 | G107: 665.244
D108: 52 | E108: 3.35819 | F108: 40.1657 | G108: 664.01
D109: 52.5 | E109: 3.35189 | F109: 40.5646 | G109: 662.765
D110: 53 | E110: 3.34549 | F110: 40.9637 | G110: 661.5
D111: 53.5 | E111: 3.33902 | F111: 41.363 | G111: 660.22
D112: 54 | E112: 3.33249 | F112: 41.7625 | G112: 658.929
D113: 54.5 | E113: 3.3259 | F113: 42.162 | G113: 657.625
D114: 55 | E114: 3.31927 | F114: 42.5615 | G114: 656.314
D115: 55.5 | E115: 3.31259 | F115: 42.9612 | G115: 654.994
D116: 56 | E116: 3.30589 | F116: 43.3608 | G116: 653.669
...

Sheet C2L4
B2: -0.001 | C2: -1 | D2: b/200 | I2: b/300 | N2: b/100
A3: U_14__14 | B3: RF_14__14 | D3: X | E3: LPF | F3: U_14__14 | G3: RF_14__14 | I3: X | J3: LPF | K3: U_14__14 | L3: RF_14__14 | N3: X | O3: LPF | P3: U_14__14 | Q3: RF_14__14
A4: 0.053108786 | B4: 8.5106279 | D4: 0 | E4: 0 | F4: 0 | G4: 0 | I4: 0 | J4: 0 | K4: 0.0302823 | L4: -7.42421e-07 | N4: 0 | O4: 0 | P4: 0.0877152 | Q4: 3.35528e-07
A5: 0.12152093 | B5: 89.549885 | D5: 0.5 | E5: 0.493248 | F5: 0.056125 | G5: 68.0755 | I5: 0.5 | J5: 0.493357 | K5: -0.0726714 | L5: 68.0905 | N5: 0.5 | O5: 0.492704 | P5: -0.00732933 | Q5: 68.0004
A6: 0.33160548 | B6: 196.67831 | D6: 1 | E6: 0.964184 | F6: 0.19124 | G6: 133.072 | I6: 1 | J6: 0.964722 | K6: -0.209746 | L6: 133.146 | N6: 1 | O6: 0.961456 | P6: -0.13904 | Q6: 132.695
A7: 1.0768425 | B7: 292.78098 | D7: 1.5 | E7: 1.3953 | F7: 0.370686 | G7: 192.573 | I7: 1.5 | J7: 1.39679 | K7: -0.390508 | L7: 192.779 | N7: 1.5 | O7: 1.38762 | P7: -0.318289 | Q7: 191.514
A8: 1.8945072 | B8: 357.28526 | D8: 2 | E8: 1.76469 | F8: 0.597981 | G8: 243.558 | I8: 2 | J8: 1.76784 | K8: -0.618379 | L8: 243.993 | N8: 2 | O8: 1.74845 | P8: -0.548616 | Q8: 241.317
A9: 3.3544724 | B9: 405.26191 | D9: 2.5 | E9: 2.0594 | F9: 0.865009 | G9: 284.237 | I9: 2.5 | J9: 2.0647 | K9: -0.885426 | L9: 284.968 | N9: 2.5 | O9: 2.03217 | P9: -0.820533 | Q9: 280.469
A10: 4.9223201 | B10: 427.13225 | D10: 3 | E10: 2.28464 | F10: 1.15784 | G10: 315.325 | I10: 3 | J10: 2.29213 | K10: -1.17794 | L10: 316.358 | N10: 3 | O10: 2.24644 | P10: -1.11891 | Q10: 310.04
A11: 6.9895227 | B11: 442.10016 | D11: 3.5 | E11: 2.45561 | F11: 1.46532 | G11: 338.92 | I11: 3.5 | J11: 2.46505 | K11: -1.4849 | L11: 340.222 | N11: 3.5 | O11: 2.40782 | P11: -1.4322 | Q11: 332.324
A12: 10.126247 | B12: 456.99462 | D12: 4 | E12: 2.5872 | F12: 1.7809 | G12: 357.079 | I12: 4 | J12: 2.59826 | K12: -1.79979 | L12: 358.605 | N12: 4 | O12: 2.53144 | P12: -1.75377 | Q12: 349.384
A13: 15.330957 | B13: 464.87891 | D13: 4.5 | E13: 2.69058 | F13: 2.10107 | G13: 371.345 | I13: 4.5 | J13: 2.70299 | K13: -2.11914 | L13: 373.058 | N13: 4.5 | O13: 2.62829 | P13: -2.08012 | Q13: 362.749
A14: 20.607164 | B14: 467.26378 | D14: 5 | E14: 2.77354 | F14: 2.42396 | G14: 382.793 | I14: 5 | J14: 2.78706 | K14: -2.44112 | L14: 384.66 | N14: 5 | O14: 2.70586 | P14: -2.40934 | Q14: 373.453
A15: 29.305595 | B15: 476.28175 | D15: 5.5 | E15: 2.8414 | F15: 2.74854 | G15: 392.157 | I15: 5.5 | J15: 2.85585 | K15: -2.76471 | L15: 394.153 | N15: 5.5 | O15: 2.76924 | P15: -2.7404 | Q15: 382.199
... A20: 70.589951 | B20: 450.09464 | D20: 8 | E20: 3.05224 | F20: 4.38246 | G20: 421.254 | I20: 8 | J20: 3.0697 | K20: -4.39296 | L20: 423.664 | N20: 8 | O20: 2.96576 | P20: -4.40817 | Q20: 409.319
D21: 8.5 | E21: 3.07931 | F21: 4.71026 | G21: 424.99 | I21: 8.5 | J21: 3.09717 | K21: -4.71953 | L21: 427.455 | N21: 8.5 | O21: 2.99095 | P21: -4.74294 | Q21: 412.795
D22: 9 | E22: 3.10332 | F22: 5.03821 | G22: 428.304 | I22: 9 | J22: 3.12153 | K22: -5.04625 | L22: 430.818 | N22: 9 | O22: 3.01328 | P22: -5.0779 | Q22: 415.877
D23: 9.5 | E23: 3.12476 | F23: 5.3663 | G23: 431.263 | I23: 9.5 | J23: 3.14329 | K23: -5.37307 | L23: 433.821 | N23: 9.5 | O23: 3.03321 | P23: -5.41304 | Q23: 418.628
D24: 10 | E24: 3.14402 | F24: 5.69449 | G24: 433.921 | I24: 10 | J24: 3.16285 | K24: -5.69999 | L24: 436.519 | N24: 10 | O24: 3.05111 | P24: -5.7483 | Q24: 421.098
D25: 10.5 | E25: 3.16142 | F25: 6.02276 | G25: 436.322 | I25: 10.5 | J25: 3.18051 | K25: -6.02697 | L25: 438.956 | N25: 10.5 | O25: 3.06727 | P25: -6.08368 | Q25: 423.328
D26: 11 | E26: 3.17721 | F26: 6.35109 | G26: 438.501 | I26: 11 | J26: 3.19654 | K26: -6.35401 | L26: 441.168 | N26: 11 | O26: 3.08192 | P26: -6.41915 | Q26: 425.35
D27: 11.5 | E27: 3.1916 | F27: 6.67949 | G27: 440.487 | I27: 11.5 | J27: 3.21115 | K27: -6.6811 | L27: 443.186 | N27: 11.5 | O27: 3.09528 | P27: -6.75469 | Q27: 427.194
D28: 12 | E28: 3.20478 | F28: 7.00792 | G28: 442.306 | I28: 12 | J28: 3.22453 | K28: -7.00823 | L28: 445.032 | N28: 12 | O28: 3.1075 | P28: -7.0903 | Q28: 428.88
D29: 12.5 | E29: 3.21688 | F29: 7.3364 | G29: 443.976 | I29: 12.5 | J29: 3.23683 | K29: -7.33539 | L29: 446.729 | N29: 12.5 | O29: 3.11871 | P29: -7.42596 | Q29: 430.428
D30: 13 | E30: 3.22804 | F30: 7.66491 | G30: 445.516 | I30: 13 | J30: 3.24816 | K30: -7.66258 | L30: 448.294 | N30: 13 | O30: 3.12905 | P30: -7.76167 | Q30: 431.854
D31: 13.5 | E31: 3.23836 | F31: 7.99345 | G31: 446.941 | I31: 13.5 | J31: 3.25865 | K31: -7.98979 | L31: 449.74 | N31: 13.5 | O31: 3.1386 | P31: -8.09742 | Q31: 433.172
D32: 14 | E32: 3.24793 | F32: 8.32202 | G32: 448.261 | I32: 14 | J32: 3.26837 | K32: -8.31702 | L32: 451.083 | N32: 14 | O32: 3.14745 | P32: -8.43321 | Q32: 434.394
... D154: 75 | E154: 3.4284 | F154: 48.4166 | G154: 473.168 | I154: 75 | J154: 3.46523 | K154: -48.2365 | L154: 478.251 | N154: 73.0781 | O154: 3.27864 | P154: -48.1532 | Q154: 452.5
D155: 75.5 | E155: 3.42741 | F155: 48.7462 | G155: 473.031 | L155: =MAX(L4:L154) -> 478.861 | Q155: =MAX(Q4:Q154) -> 456.251
D156: 76 | E156: 3.42635 | F156: 49.0759 | G156: 472.885
D157: 76.5 | E157: 3.42522 | F157: 49.4057 | G157: 472.73
D158: 77 | E158: 3.424 | F158: 49.7356 | G158: 472.561
D159: 77.5 | E159: 3.42272 | F159: 50.0655 | G159: 472.385
D160: 78 | E160: 3.42141 | F160: 50.3956 | G160: 472.203
D161: 78.5 | E161: 3.42004 | F161: 50.7257 | G161: 472.014
D162: 79 | E162: 3.41862 | F162: 51.0558 | G162: 471.818
D163: 79.5 | E163: 3.41714 | F163: 51.386 | G163: 471.614
D164: 80 | E164: 3.41563 | F164: 51.7163 | G164: 471.405
D165: 80.5 | E165: 3.41408 | F165: 52.0467 | G165: 471.192
D166: 81 | E166: 3.41247 | F166: 52.3771 | G166: 470.97
...

Sheet Al
B1: 49 | C1: Pu_exp | D1: Pu_EF | G1: Pu_EF/Pu_exp
D2: b/300 | E2: b/200 | F2: b/100 | G2: b/300 | H2: b/200 | I2: b/100
A3: 7 | B3: C1L1 | C3: 915.6 | D3: ='C1L1'!L105 -> 931.316 | E3: ='C1L1'!G80 -> 928.466 | F3: ='C1L1'!Q105 -> 910.296 | G3: =D3/$C3 -> 1.0171647 | H3: =E3/C3 -> 1.014052 | I3: =F3/C3 -> 0.99420708
A4: 8 | B4: C1L2 | C4: 656.33 | D4: ='C1L2'!L55 -> 671.05 | E4: ='C1L2'!G80 -> 668.29 | F4: ='C1L2'!Q55 -> 655.744 | G4: =D4/C4 -> 1.0224277 | H4: =E4/C4 -> 1.0182225 | I4: =F4/C4 -> 0.99910716
A5: 9 | B5: C1L3 | C5: 345.19 | D5: ='C1L3'!L105 -> 337.917 | E5: ='C1L3'!G155 -> 337.119 | F5: ='C1L3'!Q105 -> 332.981 | G5: =D5/C5 -> 0.97893044 | H5: =E5/C5 -> 0.97661867 | I5: =F5/C5 -> 0.96463107
A6: 10 | B6: C1L4 | C6: 217.3 | D6: ='C1L4'!L155 -> 209.831 | E6: ='C1L4'!G196 -> 209.416 | F6: ='C1L4'!Q155 -> 207.058 | G6: =D6/C6 -> 0.96562816 | H6: =E6/C6 -> 0.96371836 | I6: =F6/C6 -> 0.952867
A7: 11 | B7: C2L1 | C7: 1556.83 | D7: ='C2L1'!L80 -> 1524.56 | E7: ='C2L1'!G80 -> 1475.92 | F7: ='C2L1'!Q105 -> 1359.2 | G7: =D7/C7 -> 0.97927198 | H7: =E7/C7 -> 0.94802901 | I7: =F7/C7 -> 0.87305615
A8: 12 | B8: C2L2 | C8: 1087.71 | D8: ='C2L2'!L80 -> 1099.56 | E8: ='C2L2'!G80 -> 1073.49 | F8: ='C2L2'!Q105 -> 994.366 | G8: =D8/C8 -> 1.0108944 | H8: =E8/C8 -> 0.98692666 | I8: =F8/C8 -> 0.91418301
A9: 13 | B9: C2L3 | C9: 692.05 | D9: ='C2L3'!L105 -> 699.319 | E9: ='C2L3'!G155 -> 690.469 | F9: ='C2L3'!Q105 -> 656.575 | G9: =D9/C9 -> 1.0105036 | H9: =E9/C9 -> 0.99771548 | I9: =F9/C9 -> 0.94873925
A10: 14 | B10: C2L4 | C10: 483.05 | D10: ='C2L4'!L155 -> 478.861 | E10: ='C2L4'!G205 -> 474.602 | F10: ='C2L4'!Q155 -> 456.251 | G10: =D10/C10 -> 0.99132802 | H10: =E10/C10 -> 0.98251113 | I10: =F10/C10 -> 0.94452127
B11: Mean | G11: =AVERAGE(G3:G10) -> 0.99701863 | H11: =AVERAGE(H3:H10) -> 0.98597423 | I11: =AVERAGE(I3:I10) -> 0.948914
B12: COV | G12: =_xlfn.STDEV.P(G3:G10)/G11 -> 0.019698419 | H12: =_xlfn.STDEV.P(H3:H10)/H11 -> 0.022683759 | I12: =_xlfn.STDEV.P(I3:I10)/I11 -> 0.040496412
